Workbook

Sheet Comparison
A1: RIPPOTAI ARCHITECTURE | COMPARATIVE STATEMENT OF QUOTATIONS (CQ) — SAME SCOPE, MULTIPLE VENDORS
A2: Project: | E2: Client:
E3: Prepared by: | I3: Date:
A5: COMMERCIAL SUMMARY (auto-calculated — only the vendor names below are typed)
A6: Metric | G6: In-house Budget | H6: Finalised (Qualified Vendors)
A7: Sub-total | G7: ='1. Site Preparation'!G7+'2. Civil Works'!G7+'3. Waterproofing'!G7+'4. Flooring & Stone'!G7+'5. False Ceiling'!G7+'6. Carpentry'!G7+'7. Glass & Alu'!G7+'8. Electrical'!G7+'9. Plumbing'!G7+'10. HVAC'!G7+'11. Painting'!G7+'12. Loose Furniture'!G7+'13. Site Overheads'!G7 -> 100000 | I7: =N('1. Site Preparation'!H13)+N('2. Civil Works'!H13)+N('3. Waterproofing'!H13)+N('4. Flooring & Stone'!H13)+N('5. False Ceiling'!H13)+N('6. Carpentry'!H13)+N('7. Glass & Alu'!H13)+N('8. Electrical'!H13)+N('9. Plumbing'!H13)+N('10. HVAC'!H13)+N('11. Painting'!H13)+N('12. Loose Furniture'!H13)+N('13. Site Overheads'!H13) -> 0
A8: Total | G8: =G7 -> 100000 | I8: =I7 -> 0
A9: Variance vs Budget (₹) | G9: — | I9: =IF(I8=0,"",I8-$G$8)
A10: Variance vs Budget (%) | G10: — | I10: =IF(OR(I8=0,$G$8=0),"",I8/$G$8-1)
A11: Rank (L1 = lowest) | G11: — | I11: —
A12: Line items not quoted / trades pending | G12: — | I12: =COUNTBLANK('1. Site Preparation'!C13)+COUNTBLANK('2. Civil Works'!C13)+COUNTBLANK('3. Waterproofing'!C13)+COUNTBLANK('4. Flooring & Stone'!C13)+COUNTBLANK('5. False Ceiling'!C13)+COUNTBLANK('6. Carpentry'!C13)+COUNTBLANK('7. Glass & Alu'!C13)+COUNTBLANK('8. Electrical'!C13)+COUNTBLANK('9. Plumbing'!C13)+COUNTBLANK('10. HVAC'!C13)+COUNTBLANK('11. Painting'!C13)+COUNTBLANK('12. Loose Furniture'!C13)+COUNTBLANK('13. Site Overheads'!C13) -> 13
A14: SCOPE BREAKDOWN — EACH TRADE IS ITS OWN SHEET (click to open)
A15: No. | B15: Scope / Trade | G15: Sub-total | I15: BOQ Sub-total | K15: Qualified Vendor | M15: Finalised
A16: 1 | B16: 1. Site Preparation, Demolition & Debris Removal | G16: ='1. Site Preparation'!G7 -> 0 | I16: ='1. Site Preparation'!I7 -> 0 | K16: ='1. Site Preparation'!C13 -> 0 | M16: ='1. Site Preparation'!H13
A17: 2 | B17: 2. Civil Works, Masonry & Plaster | G17: ='2. Civil Works'!G7 -> 100000 | I17: ='2. Civil Works'!I7 -> 39500 | K17: ='2. Civil Works'!C13 -> 0 | M17: ='2. Civil Works'!H13
A18: 3 | B18: 3. Waterproofing | G18: ='3. Waterproofing'!G7 -> 0 | I18: ='3. Waterproofing'!I7 -> 0 | K18: ='3. Waterproofing'!C13 -> 0 | M18: ='3. Waterproofing'!H13
A19: 4 | B19: 4. Flooring & Stone | G19: ='4. Flooring & Stone'!G7 -> 0 | I19: ='4. Flooring & Stone'!I7 -> 0 | K19: ='4. Flooring & Stone'!C13 -> 0 | M19: ='4. Flooring & Stone'!H13
A20: 5 | B20: 5. False Ceiling & Drywall Partitions | G20: ='5. False Ceiling'!G7 -> 0 | I20: ='5. False Ceiling'!I7 -> 0 | K20: ='5. False Ceiling'!C13 -> 0 | M20: ='5. False Ceiling'!H13
A21: 6 | B21: 6. Carpentry & Joinery | G21: ='6. Carpentry'!G7 -> 0 | I21: ='6. Carpentry'!I7 -> 0 | K21: ='6. Carpentry'!C13 -> 0 | M21: ='6. Carpentry'!H13
A22: 7 | B22: 7. Glass, Aluminium & Hardware | G22: ='7. Glass & Alu'!G7 -> 0 | I22: ='7. Glass & Alu'!I7 -> 0 | K22: ='7. Glass & Alu'!C13 -> 0 | M22: ='7. Glass & Alu'!H13
A23: 8 | B23: 8. Electrical & Low-Voltage | G23: ='8. Electrical'!G7 -> 0 | I23: ='8. Electrical'!I7 -> 0 | K23: ='8. Electrical'!C13 -> 0 | M23: ='8. Electrical'!H13
A24: 9 | B24: 9. Plumbing & Sanitary | G24: ='9. Plumbing'!G7 -> 0 | I24: ='9. Plumbing'!I7 -> 0 | K24: ='9. Plumbing'!C13 -> 0 | M24: ='9. Plumbing'!H13
A25: 10 | B25: 10. HVAC | G25: ='10. HVAC'!G7 -> 0 | I25: ='10. HVAC'!I7 -> 0 | K25: ='10. HVAC'!C13 -> 0 | M25: ='10. HVAC'!H13
A26: 11 | B26: 11. Painting & Wall Finishes | G26: ='11. Painting'!G7 -> 0 | I26: ='11. Painting'!I7 -> 0 | K26: ='11. Painting'!C13 -> 0 | M26: ='11. Painting'!H13
A27: 12 | B27: 12. Loose Furniture & Furnishings | G27: ='12. Loose Furniture'!G7 -> 0 | I27: ='12. Loose Furniture'!I7 -> 0 | K27: ='12. Loose Furniture'!C13 -> 0 | M27: ='12. Loose Furniture'!H13
A28: 13 | B28: 13. Site Overheads, Supervision & Miscellaneous | G28: ='13. Site Overheads'!G7 -> 0 | I28: ='13. Site Overheads'!I7 -> 0 | K28: ='13. Site Overheads'!C13 -> 0 | M28: ='13. Site Overheads'!H13
A29: COMMERCIAL TERMS, QUALIFICATIONS & EXCLUSIONS (enter verbatim from each vendor's quotation)
A30: Parameter | H30: =H6 -> Finalised (Qualified Vendors) | J30: =J6 -> 0 | L30: =L6 -> 0 | N30: =N6 -> 0 | P30: Rippotai note / risk flag
A31: Quotation reference & date
A32: Payment terms (stage-wise)
A33: Advance demanded (%)
A34: Retention / security deposit
A35: Execution timeline (days from LOI)
A36: Mobilisation lead time
A37: Quote validity
A38: Freight, loading & unloading
A39: Wastage / breakage policy
A40: Site facilities expected from Rippotai
A41: Labour, T&P and scaffolding — in scope?
A42: Warranty / defect liability period
...

Sheet 1. Site Preparation
A1: RIPPOTAI ARCHITECTURE | 1. Site Preparation, Demolition & Debris Removal — COMPARATIVE STATEMENT OF QUOTATIONS | W1: =#REF! -> #REF!
A2: Project: | B2: =Comparison!B2 -> 0 | E2: Client: | F2: =Comparison!F2 -> 0 | L2: =Comparison!J2 -> 0 | W2: =J6 -> Vendor 1 — name
E3: Prepared by: | K3: Date: | W3: =L6 -> Vendor 2 — name
A5: COMMERCIAL SUMMARY — 1. Site Preparation, Demolition & Debris Removal (auto-calculated)
A6: Metric | G6: In-house Budget | H6: BOQ Rate | J6: Vendor 1 — name | L6: Vendor 2 — name | N6: Vendor 3 — name | P6: Vendor 4 — name
A7: Sub-total | G7: =G22 -> 0 | I7: =I22 -> 0 | K7: =K22 -> 0 | M7: =M22 -> 0 | O7: =O22 -> 0 | Q7: =Q22 -> 0
A8: Total | G8: =G7 -> 0 | I8: =I7 -> 0 | K8: =K7 -> 0 | M8: =M7 -> 0 | O8: =O7 -> 0 | Q8: =Q7 -> 0
A9: Variance vs Budget (₹) | G9: — | I9: =IF(I8=0,"",I8-$G$8) | K9: =IF(K8=0,"",K8-$G$8) | M9: =IF(M8=0,"",M8-$G$8) | O9: =IF(O8=0,"",O8-$G$8) | Q9: =IF(Q8=0,"",Q8-$G$8)
A10: Variance vs Budget (%) | G10: — | I10: =IF(OR(I8=0,$G$8=0),"",I8/$G$8-1) | K10: =IF(OR(K8=0,$G$8=0),"",K8/$G$8-1) | M10: =IF(OR(M8=0,$G$8=0),"",M8/$G$8-1) | O10: =IF(OR(O8=0,$G$8=0),"",O8/$G$8-1) | Q10: =IF(OR(Q8=0,$G$8=0),"",Q8/$G$8-1)
A11: Rank (L1 = lowest) | G11: — | I11: — | K11: =IF(K8=0,"",1+IF(AND(M8>0,M8<K8),1,0)+IF(AND(O8>0,O8<K8),1,0)+IF(AND(Q8>0,Q8<K8),1,0)) | M11: =IF(M8=0,"",1+IF(AND(K8>0,K8<M8),1,0)+IF(AND(O8>0,O8<M8),1,0)+IF(AND(Q8>0,Q8<M8),1,0)) | O11: =IF(O8=0,"",1+IF(AND(K8>0,K8<O8),1,0)+IF(AND(M8>0,M8<O8),1,0)+IF(AND(Q8>0,Q8<O8),1,0)) | Q11: =IF(Q8=0,"",1+IF(AND(K8>0,K8<Q8),1,0)+IF(AND(M8>0,M8<Q8),1,0)+IF(AND(O8>0,O8<Q8),1,0))
A12: Line items not quoted | G12: — | I12: =IF(I8=0,"",COUNT($E$17:$E$21)-COUNT(H17:H21)) | K12: =IF(K8=0,"",COUNT($E$17:$E$21)-COUNT(J17:J21)) | M12: =IF(M8=0,"",COUNT($E$17:$E$21)-COUNT(L17:L21)) | O12: =IF(O8=0,"",COUNT($E$17:$E$21)-COUNT(N17:N21)) | Q12: =IF(Q8=0,"",COUNT($E$17:$E$21)-COUNT(P17:P21))
A13: QUALIFIED / FINALISED VENDOR (your selection — not automatic) | F13: Finalised Sub-total | H13: =IF($C13="","",IF($C13=#REF!,#REF!,IF($C13=J6,K7,IF($C13=L6,M7,IF($C13=N6,O7,"")))))
A14: SCOPE, QUANTITY & IN-HOUSE BUDGET — 1. Site Preparation, Demolition & Debris Removal | J14: =J6 -> Vendor 1 — name | L14: =L6 -> Vendor 2 — name | N14: =N6 -> Vendor 3 — name | P14: =P6 -> Vendor 4 — name | R14: L1 ANALYSIS (auto) | V14: REMARKS
A15: S.No | B15: Item Description | C15: Specification / Make | D15: Unit | E15: Qty | F15: Budget Rate | G15: Budget Amount | H15: BOQ Rate | I15: BOQ Amount | J15: Rate | K15: Amount | L15: Rate | M15: Amount | N15: Rate | O15: Amount | P15: Rate | Q15: Amount | R15: L1 Rate | S15: L1 Vendor | T15: L1 Amount | U15: L1 vs Budget | V15: Remarks / Qualification
A16: 1. Site Preparation, Demolition & Debris Removal
A17: 1 | G17: =IF(OR($E17="",$F17=""),"",$E17*$F17) | I17: =IF(OR($E17="",H17=""),"",$E17*H17) | K17: =IF(OR($E17="",J17=""),"",$E17*J17) | M17: =IF(OR($E17="",L17=""),"",$E17*L17) | O17: =IF(OR($E17="",N17=""),"",$E17*N17) | Q17: =IF(OR($E17="",P17=""),"",$E17*P17) | R17: =IF(MIN(IF(J17=0,9.9E+30,J17),IF(L17=0,9.9E+30,L17),IF(N17=0,9.9E+30,N17),IF(P17=0,9.9E+30,P17))>9E+30,"",MIN(IF(J17=0,9.9E+30,J17),IF(L17=0,9.9E+30,L17),IF(N17=0,9.9E+30,N17),IF(P17=0,9.9E+30,P17))) | S17: =IF($R17="","",IF(J17=$R17,$J$6,IF(L17=$R17,$L$6,IF(N17=$R17,$N$6,IF(P17=$R17,$P$6,""))))) | T17: =IF(OR($R17="",$E17=""),"",$E17*$R17) | U17: =IF(OR($F17="",$F17=0,$R17=""),"",$R17/$F17-1)
A18: 2 | G18: =IF(OR($E18="",$F18=""),"",$E18*$F18) | I18: =IF(OR($E18="",H18=""),"",$E18*H18) | K18: =IF(OR($E18="",J18=""),"",$E18*J18) | M18: =IF(OR($E18="",L18=""),"",$E18*L18) | O18: =IF(OR($E18="",N18=""),"",$E18*N18) | Q18: =IF(OR($E18="",P18=""),"",$E18*P18) | R18: =IF(MIN(IF(J18=0,9.9E+30,J18),IF(L18=0,9.9E+30,L18),IF(N18=0,9.9E+30,N18),IF(P18=0,9.9E+30,P18))>9E+30,"",MIN(IF(J18=0,9.9E+30,J18),IF(L18=0,9.9E+30,L18),IF(N18=0,9.9E+30,N18),IF(P18=0,9.9E+30,P18))) | S18: =IF($R18="","",IF(J18=$R18,$J$6,IF(L18=$R18,$L$6,IF(N18=$R18,$N$6,IF(P18=$R18,$P$6,""))))) | T18: =IF(OR($R18="",$E18=""),"",$E18*$R18) | U18: =IF(OR($F18="",$F18=0,$R18=""),"",$R18/$F18-1)
A19: 3 | G19: =IF(OR($E19="",$F19=""),"",$E19*$F19) | I19: =IF(OR($E19="",H19=""),"",$E19*H19) | K19: =IF(OR($E19="",J19=""),"",$E19*J19) | M19: =IF(OR($E19="",L19=""),"",$E19*L19) | O19: =IF(OR($E19="",N19=""),"",$E19*N19) | Q19: =IF(OR($E19="",P19=""),"",$E19*P19) | R19: =IF(MIN(IF(J19=0,9.9E+30,J19),IF(L19=0,9.9E+30,L19),IF(N19=0,9.9E+30,N19),IF(P19=0,9.9E+30,P19))>9E+30,"",MIN(IF(J19=0,9.9E+30,J19),IF(L19=0,9.9E+30,L19),IF(N19=0,9.9E+30,N19),IF(P19=0,9.9E+30,P19))) | S19: =IF($R19="","",IF(J19=$R19,$J$6,IF(L19=$R19,$L$6,IF(N19=$R19,$N$6,IF(P19=$R19,$P$6,""))))) | T19: =IF(OR($R19="",$E19=""),"",$E19*$R19) | U19: =IF(OR($F19="",$F19=0,$R19=""),"",$R19/$F19-1)
A20: 4 | G20: =IF(OR($E20="",$F20=""),"",$E20*$F20) | I20: =IF(OR($E20="",H20=""),"",$E20*H20) | K20: =IF(OR($E20="",J20=""),"",$E20*J20) | M20: =IF(OR($E20="",L20=""),"",$E20*L20) | O20: =IF(OR($E20="",N20=""),"",$E20*N20) | Q20: =IF(OR($E20="",P20=""),"",$E20*P20) | R20: =IF(MIN(IF(J20=0,9.9E+30,J20),IF(L20=0,9.9E+30,L20),IF(N20=0,9.9E+30,N20),IF(P20=0,9.9E+30,P20))>9E+30,"",MIN(IF(J20=0,9.9E+30,J20),IF(L20=0,9.9E+30,L20),IF(N20=0,9.9E+30,N20),IF(P20=0,9.9E+30,P20))) | S20: =IF($R20="","",IF(J20=$R20,$J$6,IF(L20=$R20,$L$6,IF(N20=$R20,$N$6,IF(P20=$R20,$P$6,""))))) | T20: =IF(OR($R20="",$E20=""),"",$E20*$R20) | U20: =IF(OR($F20="",$F20=0,$R20=""),"",$R20/$F20-1)
A21: 5 | G21: =IF(OR($E21="",$F21=""),"",$E21*$F21) | I21: =IF(OR($E21="",H21=""),"",$E21*H21) | K21: =IF(OR($E21="",J21=""),"",$E21*J21) | M21: =IF(OR($E21="",L21=""),"",$E21*L21) | O21: =IF(OR($E21="",N21=""),"",$E21*N21) | Q21: =IF(OR($E21="",P21=""),"",$E21*P21) | R21: =IF(MIN(IF(J21=0,9.9E+30,J21),IF(L21=0,9.9E+30,L21),IF(N21=0,9.9E+30,N21),IF(P21=0,9.9E+30,P21))>9E+30,"",MIN(IF(J21=0,9.9E+30,J21),IF(L21=0,9.9E+30,L21),IF(N21=0,9.9E+30,N21),IF(P21=0,9.9E+30,P21))) | S21: =IF($R21="","",IF(J21=$R21,$J$6,IF(L21=$R21,$L$6,IF(N21=$R21,$N$6,IF(P21=$R21,$P$6,""))))) | T21: =IF(OR($R21="",$E21=""),"",$E21*$R21) | U21: =IF(OR($F21="",$F21=0,$R21=""),"",$R21/$F21-1)
A22: Sub-total — Site Preparation, Demolition & Debris Removal | G22: =SUM(G17:G21) -> 0 | I22: =SUM(I17:I21) -> 0 | K22: =SUM(K17:K21) -> 0 | M22: =SUM(M17:M21) -> 0 | O22: =SUM(O17:O21) -> 0 | Q22: =SUM(Q17:Q21) -> 0 | T22: =SUM(T17:T21) -> 0

Sheet 2. Civil Works
A1: RIPPOTAI ARCHITECTURE | 2. Civil Works, Masonry & Plaster — COMPARATIVE STATEMENT OF QUOTATIONS | Y1: =J6 -> Vendor 1 — name
A2: Project: | B2: =Comparison!B2 -> 0 | E2: Client: | F2: =Comparison!F2 -> 0 | L2: =Comparison!J2 -> 0 | Y2: =L6 -> Vendor 2 — name
E3: Prepared by: | K3: Date: | Y3: =N6 -> Vendor 3 — name
A5: COMMERCIAL SUMMARY — 2. Civil Works, Masonry & Plaster (auto-calculated)
A6: Metric | G6: In-house Budget | H6: BOQ Rate | J6: Vendor 1 — name | L6: Vendor 2 — name | N6: Vendor 3 — name | P6: Vendor 4 — name
A7: Sub-total | G7: 100000 | I7: =I22 -> 39500 | K7: =K22 -> 45350 | M7: =M22 -> 44900 | O7: =O22 -> 64250 | Q7: =Q22 -> 111000
A8: Total | G8: =G7 -> 100000 | I8: =I7 -> 39500 | K8: =K7 -> 45350 | M8: =M7 -> 44900 | O8: =O7 -> 64250 | Q8: =Q7 -> 111000
A9: Variance vs Budget (₹) | G9: — | I9: =IF(I8=0,"",I8-$G$8) -> -60500 | K9: =IF(K8=0,"",K8-$G$8) -> -54650 | M9: =IF(M8=0,"",M8-$G$8) -> -55100 | O9: =IF(O8=0,"",O8-$G$8) -> -35750 | Q9: =IF(Q8=0,"",Q8-$G$8) -> 11000
A10: Variance vs Budget (%) | G10: — | I10: =IF(OR(I8=0,$G$8=0),"",I8/$G$8-1) -> -0.605 | K10: =IF(OR(K8=0,$G$8=0),"",K8/$G$8-1) -> -0.5465 | M10: =IF(OR(M8=0,$G$8=0),"",M8/$G$8-1) -> -0.551 | O10: =IF(OR(O8=0,$G$8=0),"",O8/$G$8-1) -> -0.3575 | Q10: =IF(OR(Q8=0,$G$8=0),"",Q8/$G$8-1) -> 0.11
A11: Rank (L1 = lowest) | G11: — | I11: — | K11: =IF(K8=0,"",1+IF(AND(M8>0,M8<K8),1,0)+IF(AND(O8>0,O8<K8),1,0)+IF(AND(Q8>0,Q8<K8),1,0)) -> 2 | M11: =IF(M8=0,"",1+IF(AND(K8>0,K8<M8),1,0)+IF(AND(O8>0,O8<M8),1,0)+IF(AND(Q8>0,Q8<M8),1,0)) -> 1 | O11: =IF(O8=0,"",1+IF(AND(K8>0,K8<O8),1,0)+IF(AND(M8>0,M8<O8),1,0)+IF(AND(Q8>0,Q8<O8),1,0)) -> 3 | Q11: =IF(Q8=0,"",1+IF(AND(K8>0,K8<Q8),1,0)+IF(AND(M8>0,M8<Q8),1,0)+IF(AND(O8>0,O8<Q8),1,0)) -> 4
A12: Line items not quoted | G12: — | I12: =IF(I8=0,"",COUNT($E$17:$E$21)-COUNT(H17:H21)) -> 0 | K12: =IF(K8=0,"",COUNT($E$17:$E$21)-COUNT(J17:J21)) -> 0 | M12: =IF(M8=0,"",COUNT($E$17:$E$21)-COUNT(L17:L21)) -> 0 | O12: =IF(O8=0,"",COUNT($E$17:$E$21)-COUNT(N17:N21)) -> 0 | Q12: =IF(Q8=0,"",COUNT($E$17:$E$21)-COUNT(P17:P21)) -> 0
A13: QUALIFIED / FINALISED VENDOR (your selection — not automatic) | F13: Finalised Sub-total | H13: =IF($C13="","",IF($C13=J6,K7,IF($C13=L6,M7,IF($C13=N6,O7,IF($C13=P6,Q7,"")))))
A14: SCOPE, QUANTITY & IN-HOUSE BUDGET — 2. Civil Works, Masonry & Plaster | J14: =J6 -> Vendor 1 — name | L14: =L6 -> Vendor 2 — name | N14: =N6 -> Vendor 3 — name | P14: =P6 -> Vendor 4 — name | R14: L1 ANALYSIS (auto) | V14: REMARKS
A15: S.No | B15: Item Description | C15: Specification / Make | D15: Unit | E15: Qty | F15: Budget Rate | G15: Budget Amount | H15: BOQ Rate | I15: BOQ Amount | J15: Rate | K15: Amount | L15: Rate | M15: Amount | N15: Rate | O15: Amount | P15: Rate | Q15: Amount | R15: L1 Rate | S15: L1 Vendor | T15: L1 Amount | U15: L1 vs Budget | V15: Remarks / Qualification
A16: 2. Civil Works, Masonry & Plaster
A17: 6 | B17: metal staircase | D17: Sqft | E17: 100 | F17: 125 | G17: =IF(OR($E17="",$F17=""),"",$E17*$F17) -> 12500 | H17: 105 | I17: =IF(OR($E17="",H17=""),"",$E17*H17) -> 10500 | J17: 155 | K17: =IF(OR($E17="",J17=""),"",$E17*J17) -> 15500 | L17: 140 | M17: =IF(OR($E17="",L17=""),"",$E17*L17) -> 14000 | N17: 130 | O17: =IF(OR($E17="",N17=""),"",$E17*N17) -> 13000 | P17: 100 | Q17: =IF(OR($E17="",P17=""),"",$E17*P17) -> 10000 | R17: =IF(MIN(IF(J17=0,9.9E+30,J17),IF(L17=0,9.9E+30,L17),IF(N17=0,9.9E+30,N17),IF(P17=0,9.9E+30,P17))>9E+30,"",MIN(IF(J17=0,9.9E+30,J17),IF(L17=0,9.9E+30,L17),IF(N17=0,9.9E+30,N17),IF(P17=0,9.9E+30,P17))) -> 100 | S17: =IF($R17="","",IF(J17=$R17,$J$6,IF(L17=$R17,$L$6,IF(N17=$R17,$N$6,IF(P17=$R17,$P$6,""))))) -> Vendor 4 — name | T17: =IF(OR($R17="",$E17=""),"",$E17*$R17) -> 10000 | U17: =IF(OR($F17="",$F17=0,$R17=""),"",$R17/$F17-1) -> -0.2
A18: 7 | D18: Sqft | E18: 200 | F18: 100 | G18: =IF(OR($E18="",$F18=""),"",$E18*$F18) -> 20000 | H18: 100 | I18: =IF(OR($E18="",H18=""),"",$E18*H18) -> 20000 | J18: 102 | K18: =IF(OR($E18="",J18=""),"",$E18*J18) -> 20400 | L18: 105 | M18: =IF(OR($E18="",L18=""),"",$E18*L18) -> 21000 | N18: 200 | O18: =IF(OR($E18="",N18=""),"",$E18*N18) -> 40000 | P18: 100 | Q18: =IF(OR($E18="",P18=""),"",$E18*P18) -> 20000 | R18: =IF(MIN(IF(J18=0,9.9E+30,J18),IF(L18=0,9.9E+30,L18),IF(N18=0,9.9E+30,N18),IF(P18=0,9.9E+30,P18))>9E+30,"",MIN(IF(J18=0,9.9E+30,J18),IF(L18=0,9.9E+30,L18),IF(N18=0,9.9E+30,N18),IF(P18=0,9.9E+30,P18))) -> 100 | S18: =IF($R18="","",IF(J18=$R18,$J$6,IF(L18=$R18,$L$6,IF(N18=$R18,$N$6,IF(P18=$R18,$P$6,""))))) -> Vendor 4 — name | T18: =IF(OR($R18="",$E18=""),"",$E18*$R18) -> 20000 | U18: =IF(OR($F18="",$F18=0,$R18=""),"",$R18/$F18-1) -> 0
A19: 8 | D19: Sqft | E19: 90 | F19: 120 | G19: =IF(OR($E19="",$F19=""),"",$E19*$F19) -> 10800 | H19: 100 | I19: =IF(OR($E19="",H19=""),"",$E19*H19) -> 9000 | J19: 105 | K19: =IF(OR($E19="",J19=""),"",$E19*J19) -> 9450 | L19: 110 | M19: =IF(OR($E19="",L19=""),"",$E19*L19) -> 9900 | N19: 125 | O19: =IF(OR($E19="",N19=""),"",$E19*N19) -> 11250 | P19: 900 | Q19: =IF(OR($E19="",P19=""),"",$E19*P19) -> 81000 | R19: =IF(MIN(IF(J19=0,9.9E+30,J19),IF(L19=0,9.9E+30,L19),IF(N19=0,9.9E+30,N19),IF(P19=0,9.9E+30,P19))>9E+30,"",MIN(IF(J19=0,9.9E+30,J19),IF(L19=0,9.9E+30,L19),IF(N19=0,9.9E+30,N19),IF(P19=0,9.9E+30,P19))) -> 105 | S19: =IF($R19="","",IF(J19=$R19,$J$6,IF(L19=$R19,$L$6,IF(N19=$R19,$N$6,IF(P19=$R19,$P$6,""))))) -> Vendor 1 — name | T19: =IF(OR($R19="",$E19=""),"",$E19*$R19) -> 9450 | U19: =IF(OR($F19="",$F19=0,$R19=""),"",$R19/$F19-1) -> -0.125
A20: 9 | G20: =IF(OR($E20="",$F20=""),"",$E20*$F20) | I20: =IF(OR($E20="",H20=""),"",$E20*H20) | K20: =IF(OR($E20="",J20=""),"",$E20*J20) | M20: =IF(OR($E20="",L20=""),"",$E20*L20) | O20: =IF(OR($E20="",N20=""),"",$E20*N20) | Q20: =IF(OR($E20="",P20=""),"",$E20*P20) | R20: =IF(MIN(IF(J20=0,9.9E+30,J20),IF(L20=0,9.9E+30,L20),IF(N20=0,9.9E+30,N20),IF(P20=0,9.9E+30,P20))>9E+30,"",MIN(IF(J20=0,9.9E+30,J20),IF(L20=0,9.9E+30,L20),IF(N20=0,9.9E+30,N20),IF(P20=0,9.9E+30,P20))) | S20: =IF($R20="","",IF(J20=$R20,$J$6,IF(L20=$R20,$L$6,IF(N20=$R20,$N$6,IF(P20=$R20,$P$6,""))))) | T20: =IF(OR($R20="",$E20=""),"",$E20*$R20) | U20: =IF(OR($F20="",$F20=0,$R20=""),"",$R20/$F20-1)
A21: 10 | G21: =IF(OR($E21="",$F21=""),"",$E21*$F21) | I21: =IF(OR($E21="",H21=""),"",$E21*H21) | K21: =IF(OR($E21="",J21=""),"",$E21*J21) | M21: =IF(OR($E21="",L21=""),"",$E21*L21) | O21: =IF(OR($E21="",N21=""),"",$E21*N21) | Q21: =IF(OR($E21="",P21=""),"",$E21*P21) | R21: =IF(MIN(IF(J21=0,9.9E+30,J21),IF(L21=0,9.9E+30,L21),IF(N21=0,9.9E+30,N21),IF(P21=0,9.9E+30,P21))>9E+30,"",MIN(IF(J21=0,9.9E+30,J21),IF(L21=0,9.9E+30,L21),IF(N21=0,9.9E+30,N21),IF(P21=0,9.9E+30,P21))) | S21: =IF($R21="","",IF(J21=$R21,$J$6,IF(L21=$R21,$L$6,IF(N21=$R21,$N$6,IF(P21=$R21,$P$6,""))))) | T21: =IF(OR($R21="",$E21=""),"",$E21*$R21) | U21: =IF(OR($F21="",$F21=0,$R21=""),"",$R21/$F21-1)
A22: Sub-total — Civil Works, Masonry & Plaster | G22: =SUM(G17:G21) -> 43300 | I22: =SUM(I17:I21) -> 39500 | K22: =SUM(K17:K21) -> 45350 | M22: =SUM(M17:M21) -> 44900 | O22: =SUM(O17:O21) -> 64250 | Q22: =SUM(Q17:Q21) -> 111000 | T22: =SUM(T17:T21) -> 39450

Sheet 3. Waterproofing
A1: RIPPOTAI ARCHITECTURE | 3. Waterproofing — COMPARATIVE STATEMENT OF QUOTATIONS | Y1: =J6 -> Vendor 1 — name
A2: Project: | B2: =Comparison!B2 -> 0 | E2: Client: | F2: =Comparison!F2 -> 0 | L2: =Comparison!J2 -> 0 | Y2: =L6 -> Vendor 2 — name
E3: Prepared by: | K3: Date: | Y3: =N6 -> Vendor 3 — name
A5: COMMERCIAL SUMMARY — 3. Waterproofing (auto-calculated)
A6: Metric | G6: In-house Budget | H6: BOQ Rate | J6: Vendor 1 — name | L6: Vendor 2 — name | N6: Vendor 3 — name | P6: Vendor 4 — name
A7: Sub-total | G7: =G21 -> 0 | I7: =I21 -> 0 | K7: =K21 -> 0 | M7: =M21 -> 0 | O7: =O21 -> 0 | Q7: =Q21 -> 0
A8: Total | G8: =G7 -> 0 | I8: =I7 -> 0 | K8: =K7 -> 0 | M8: =M7 -> 0 | O8: =O7 -> 0 | Q8: =Q7 -> 0
A9: Variance vs Budget (₹) | G9: — | I9: =IF(I8=0,"",I8-$G$8) | K9: =IF(K8=0,"",K8-$G$8) | M9: =IF(M8=0,"",M8-$G$8) | O9: =IF(O8=0,"",O8-$G$8) | Q9: =IF(Q8=0,"",Q8-$G$8)
A10: Variance vs Budget (%) | G10: — | I10: =IF(OR(I8=0,$G$8=0),"",I8/$G$8-1) | K10: =IF(OR(K8=0,$G$8=0),"",K8/$G$8-1) | M10: =IF(OR(M8=0,$G$8=0),"",M8/$G$8-1) | O10: =IF(OR(O8=0,$G$8=0),"",O8/$G$8-1) | Q10: =IF(OR(Q8=0,$G$8=0),"",Q8/$G$8-1)
A11: Rank (L1 = lowest) | G11: — | I11: — | K11: =IF(K8=0,"",1+IF(AND(M8>0,M8<K8),1,0)+IF(AND(O8>0,O8<K8),1,0)+IF(AND(Q8>0,Q8<K8),1,0)) | M11: =IF(M8=0,"",1+IF(AND(K8>0,K8<M8),1,0)+IF(AND(O8>0,O8<M8),1,0)+IF(AND(Q8>0,Q8<M8),1,0)) | O11: =IF(O8=0,"",1+IF(AND(K8>0,K8<O8),1,0)+IF(AND(M8>0,M8<O8),1,0)+IF(AND(Q8>0,Q8<O8),1,0)) | Q11: =IF(Q8=0,"",1+IF(AND(K8>0,K8<Q8),1,0)+IF(AND(M8>0,M8<Q8),1,0)+IF(AND(O8>0,O8<Q8),1,0))
A12: Line items not quoted | G12: — | I12: =IF(I8=0,"",COUNT($E$17:$E$20)-COUNT(H17:H20)) | K12: =IF(K8=0,"",COUNT($E$17:$E$20)-COUNT(J17:J20)) | M12: =IF(M8=0,"",COUNT($E$17:$E$20)-COUNT(L17:L20)) | O12: =IF(O8=0,"",COUNT($E$17:$E$20)-COUNT(N17:N20)) | Q12: =IF(Q8=0,"",COUNT($E$17:$E$20)-COUNT(P17:P20))
A13: QUALIFIED / FINALISED VENDOR (your selection — not automatic) | F13: Finalised Sub-total | H13: =IF($C13="","",IF($C13=J6,K7,IF($C13=L6,M7,IF($C13=N6,O7,IF($C13=P6,Q7,"")))))
A14: SCOPE, QUANTITY & IN-HOUSE BUDGET — 3. Waterproofing | J14: =J6 -> Vendor 1 — name | L14: =L6 -> Vendor 2 — name | N14: =N6 -> Vendor 3 — name | P14: =P6 -> Vendor 4 — name | R14: L1 ANALYSIS (auto) | V14: REMARKS
A15: S.No | B15: Item Description | C15: Specification / Make | D15: Unit | E15: Qty | F15: Budget Rate | G15: Budget Amount | H15: BOQ Rate | I15: BOQ Amount | J15: Rate | K15: Amount | L15: Rate | M15: Amount | N15: Rate | O15: Amount | P15: Rate | Q15: Amount | R15: L1 Rate | S15: L1 Vendor | T15: L1 Amount | U15: L1 vs Budget | V15: Remarks / Qualification
A16: 3. Waterproofing
A17: 10 | G17: =IF(OR($E17="",$F17=""),"",$E17*$F17) | I17: =IF(OR($E17="",H17=""),"",$E17*H17) | K17: =IF(OR($E17="",J17=""),"",$E17*J17) | M17: =IF(OR($E17="",L17=""),"",$E17*L17) | O17: =IF(OR($E17="",N17=""),"",$E17*N17) | Q17: =IF(OR($E17="",P17=""),"",$E17*P17) | R17: =IF(MIN(IF(J17=0,9.9E+30,J17),IF(L17=0,9.9E+30,L17),IF(N17=0,9.9E+30,N17),IF(P17=0,9.9E+30,P17))>9E+30,"",MIN(IF(J17=0,9.9E+30,J17),IF(L17=0,9.9E+30,L17),IF(N17=0,9.9E+30,N17),IF(P17=0,9.9E+30,P17))) | S17: =IF($R17="","",IF(J17=$R17,$J$6,IF(L17=$R17,$L$6,IF(N17=$R17,$N$6,IF(P17=$R17,$P$6,""))))) | T17: =IF(OR($R17="",$E17=""),"",$E17*$R17) | U17: =IF(OR($F17="",$F17=0,$R17=""),"",$R17/$F17-1)
A18: 11 | G18: =IF(OR($E18="",$F18=""),"",$E18*$F18) | I18: =IF(OR($E18="",H18=""),"",$E18*H18) | K18: =IF(OR($E18="",J18=""),"",$E18*J18) | M18: =IF(OR($E18="",L18=""),"",$E18*L18) | O18: =IF(OR($E18="",N18=""),"",$E18*N18) | Q18: =IF(OR($E18="",P18=""),"",$E18*P18) | R18: =IF(MIN(IF(J18=0,9.9E+30,J18),IF(L18=0,9.9E+30,L18),IF(N18=0,9.9E+30,N18),IF(P18=0,9.9E+30,P18))>9E+30,"",MIN(IF(J18=0,9.9E+30,J18),IF(L18=0,9.9E+30,L18),IF(N18=0,9.9E+30,N18),IF(P18=0,9.9E+30,P18))) | S18: =IF($R18="","",IF(J18=$R18,$J$6,IF(L18=$R18,$L$6,IF(N18=$R18,$N$6,IF(P18=$R18,$P$6,""))))) | T18: =IF(OR($R18="",$E18=""),"",$E18*$R18) | U18: =IF(OR($F18="",$F18=0,$R18=""),"",$R18/$F18-1)
A19: 12 | G19: =IF(OR($E19="",$F19=""),"",$E19*$F19) | I19: =IF(OR($E19="",H19=""),"",$E19*H19) | K19: =IF(OR($E19="",J19=""),"",$E19*J19) | M19: =IF(OR($E19="",L19=""),"",$E19*L19) | O19: =IF(OR($E19="",N19=""),"",$E19*N19) | Q19: =IF(OR($E19="",P19=""),"",$E19*P19) | R19: =IF(MIN(IF(J19=0,9.9E+30,J19),IF(L19=0,9.9E+30,L19),IF(N19=0,9.9E+30,N19),IF(P19=0,9.9E+30,P19))>9E+30,"",MIN(IF(J19=0,9.9E+30,J19),IF(L19=0,9.9E+30,L19),IF(N19=0,9.9E+30,N19),IF(P19=0,9.9E+30,P19))) | S19: =IF($R19="","",IF(J19=$R19,$J$6,IF(L19=$R19,$L$6,IF(N19=$R19,$N$6,IF(P19=$R19,$P$6,""))))) | T19: =IF(OR($R19="",$E19=""),"",$E19*$R19) | U19: =IF(OR($F19="",$F19=0,$R19=""),"",$R19/$F19-1)
A20: 13 | G20: =IF(OR($E20="",$F20=""),"",$E20*$F20) | I20: =IF(OR($E20="",H20=""),"",$E20*H20) | K20: =IF(OR($E20="",J20=""),"",$E20*J20) | M20: =IF(OR($E20="",L20=""),"",$E20*L20) | O20: =IF(OR($E20="",N20=""),"",$E20*N20) | Q20: =IF(OR($E20="",P20=""),"",$E20*P20) | R20: =IF(MIN(IF(J20=0,9.9E+30,J20),IF(L20=0,9.9E+30,L20),IF(N20=0,9.9E+30,N20),IF(P20=0,9.9E+30,P20))>9E+30,"",MIN(IF(J20=0,9.9E+30,J20),IF(L20=0,9.9E+30,L20),IF(N20=0,9.9E+30,N20),IF(P20=0,9.9E+30,P20))) | S20: =IF($R20="","",IF(J20=$R20,$J$6,IF(L20=$R20,$L$6,IF(N20=$R20,$N$6,IF(P20=$R20,$P$6,""))))) | T20: =IF(OR($R20="",$E20=""),"",$E20*$R20) | U20: =IF(OR($F20="",$F20=0,$R20=""),"",$R20/$F20-1)
A21: Sub-total — Waterproofing | G21: =SUM(G17:G20) -> 0 | I21: =SUM(I17:I20) -> 0 | K21: =SUM(K17:K20) -> 0 | M21: =SUM(M17:M20) -> 0 | O21: =SUM(O17:O20) -> 0 | Q21: =SUM(Q17:Q20) -> 0 | T21: =SUM(T17:T20) -> 0

Sheet 4. Flooring & Stone
A1: RIPPOTAI ARCHITECTURE | 4. Flooring & Stone — COMPARATIVE STATEMENT OF QUOTATIONS | Y1: =J6 -> Vendor 1 — name
A2: Project: | B2: =Comparison!B2 -> 0 | E2: Client: | F2: =Comparison!F2 -> 0 | L2: =Comparison!J2 -> 0 | Y2: =L6 -> Vendor 2 — name
E3: Prepared by: | K3: Date: | Y3: =N6 -> Vendor 3 — name
A5: COMMERCIAL SUMMARY — 4. Flooring & Stone (auto-calculated)
A6: Metric | G6: In-house Budget | H6: BOQ Rate | J6: Vendor 1 — name | L6: Vendor 2 — name | N6: Vendor 3 — name | P6: Vendor 4 — name
A7: Sub-total | G7: =G21 -> 0 | I7: =I21 -> 0 | K7: =K21 -> 0 | M7: =M21 -> 0 | O7: =O21 -> 0 | Q7: =Q21 -> 0
A8: Total | G8: =G7 -> 0 | I8: =I7 -> 0 | K8: =K7 -> 0 | M8: =M7 -> 0 | O8: =O7 -> 0 | Q8: =Q7 -> 0
A9: Variance vs Budget (₹) | G9: — | I9: =IF(I8=0,"",I8-$G$8) | K9: =IF(K8=0,"",K8-$G$8) | M9: =IF(M8=0,"",M8-$G$8) | O9: =IF(O8=0,"",O8-$G$8) | Q9: =IF(Q8=0,"",Q8-$G$8)
A10: Variance vs Budget (%) | G10: — | I10: =IF(OR(I8=0,$G$8=0),"",I8/$G$8-1) | K10: =IF(OR(K8=0,$G$8=0),"",K8/$G$8-1) | M10: =IF(OR(M8=0,$G$8=0),"",M8/$G$8-1) | O10: =IF(OR(O8=0,$G$8=0),"",O8/$G$8-1) | Q10: =IF(OR(Q8=0,$G$8=0),"",Q8/$G$8-1)
A11: Rank (L1 = lowest) | G11: — | I11: — | K11: =IF(K8=0,"",1+IF(AND(M8>0,M8<K8),1,0)+IF(AND(O8>0,O8<K8),1,0)+IF(AND(Q8>0,Q8<K8),1,0)) | M11: =IF(M8=0,"",1+IF(AND(K8>0,K8<M8),1,0)+IF(AND(O8>0,O8<M8),1,0)+IF(AND(Q8>0,Q8<M8),1,0)) | O11: =IF(O8=0,"",1+IF(AND(K8>0,K8<O8),1,0)+IF(AND(M8>0,M8<O8),1,0)+IF(AND(Q8>0,Q8<O8),1,0)) | Q11: =IF(Q8=0,"",1+IF(AND(K8>0,K8<Q8),1,0)+IF(AND(M8>0,M8<Q8),1,0)+IF(AND(O8>0,O8<Q8),1,0))
A12: Line items not quoted | G12: — | I12: =IF(I8=0,"",COUNT($E$17:$E$20)-COUNT(H17:H20)) | K12: =IF(K8=0,"",COUNT($E$17:$E$20)-COUNT(J17:J20)) | M12: =IF(M8=0,"",COUNT($E$17:$E$20)-COUNT(L17:L20)) | O12: =IF(O8=0,"",COUNT($E$17:$E$20)-COUNT(N17:N20)) | Q12: =IF(Q8=0,"",COUNT($E$17:$E$20)-COUNT(P17:P20))
A13: QUALIFIED / FINALISED VENDOR (your selection — not automatic) | F13: Finalised Sub-total | H13: =IF($C13="","",IF($C13=J6,K7,IF($C13=L6,M7,IF($C13=N6,O7,IF($C13=P6,Q7,"")))))
A14: SCOPE, QUANTITY & IN-HOUSE BUDGET — 4. Flooring & Stone | J14: =J6 -> Vendor 1 — name | L14: =L6 -> Vendor 2 — name | N14: =N6 -> Vendor 3 — name | P14: =P6 -> Vendor 4 — name | R14: L1 ANALYSIS (auto) | V14: REMARKS
A15: S.No | B15: Item Description | C15: Specification / Make | D15: Unit | E15: Qty | F15: Budget Rate | G15: Budget Amount | H15: BOQ Rate | I15: BOQ Amount | J15: Rate | K15: Amount | L15: Rate | M15: Amount | N15: Rate | O15: Amount | P15: Rate | Q15: Amount | R15: L1 Rate | S15: L1 Vendor | T15: L1 Amount | U15: L1 vs Budget | V15: Remarks / Qualification
A16: 4. Flooring & Stone
A17: 14 | G17: =IF(OR($E17="",$F17=""),"",$E17*$F17) | I17: =IF(OR($E17="",H17=""),"",$E17*H17) | K17: =IF(OR($E17="",J17=""),"",$E17*J17) | M17: =IF(OR($E17="",L17=""),"",$E17*L17) | O17: =IF(OR($E17="",N17=""),"",$E17*N17) | Q17: =IF(OR($E17="",P17=""),"",$E17*P17) | R17: =IF(MIN(IF(J17=0,9.9E+30,J17),IF(L17=0,9.9E+30,L17),IF(N17=0,9.9E+30,N17),IF(P17=0,9.9E+30,P17))>9E+30,"",MIN(IF(J17=0,9.9E+30,J17),IF(L17=0,9.9E+30,L17),IF(N17=0,9.9E+30,N17),IF(P17=0,9.9E+30,P17))) | S17: =IF($R17="","",IF(J17=$R17,$J$6,IF(L17=$R17,$L$6,IF(N17=$R17,$N$6,IF(P17=$R17,$P$6,""))))) | T17: =IF(OR($R17="",$E17=""),"",$E17*$R17) | U17: =IF(OR($F17="",$F17=0,$R17=""),"",$R17/$F17-1)
A18: 15 | G18: =IF(OR($E18="",$F18=""),"",$E18*$F18) | I18: =IF(OR($E18="",H18=""),"",$E18*H18) | K18: =IF(OR($E18="",J18=""),"",$E18*J18) | M18: =IF(OR($E18="",L18=""),"",$E18*L18) | O18: =IF(OR($E18="",N18=""),"",$E18*N18) | Q18: =IF(OR($E18="",P18=""),"",$E18*P18) | R18: =IF(MIN(IF(J18=0,9.9E+30,J18),IF(L18=0,9.9E+30,L18),IF(N18=0,9.9E+30,N18),IF(P18=0,9.9E+30,P18))>9E+30,"",MIN(IF(J18=0,9.9E+30,J18),IF(L18=0,9.9E+30,L18),IF(N18=0,9.9E+30,N18),IF(P18=0,9.9E+30,P18))) | S18: =IF($R18="","",IF(J18=$R18,$J$6,IF(L18=$R18,$L$6,IF(N18=$R18,$N$6,IF(P18=$R18,$P$6,""))))) | T18: =IF(OR($R18="",$E18=""),"",$E18*$R18) | U18: =IF(OR($F18="",$F18=0,$R18=""),"",$R18/$F18-1)
A19: 16 | G19: =IF(OR($E19="",$F19=""),"",$E19*$F19) | I19: =IF(OR($E19="",H19=""),"",$E19*H19) | K19: =IF(OR($E19="",J19=""),"",$E19*J19) | M19: =IF(OR($E19="",L19=""),"",$E19*L19) | O19: =IF(OR($E19="",N19=""),"",$E19*N19) | Q19: =IF(OR($E19="",P19=""),"",$E19*P19) | R19: =IF(MIN(IF(J19=0,9.9E+30,J19),IF(L19=0,9.9E+30,L19),IF(N19=0,9.9E+30,N19),IF(P19=0,9.9E+30,P19))>9E+30,"",MIN(IF(J19=0,9.9E+30,J19),IF(L19=0,9.9E+30,L19),IF(N19=0,9.9E+30,N19),IF(P19=0,9.9E+30,P19))) | S19: =IF($R19="","",IF(J19=$R19,$J$6,IF(L19=$R19,$L$6,IF(N19=$R19,$N$6,IF(P19=$R19,$P$6,""))))) | T19: =IF(OR($R19="",$E19=""),"",$E19*$R19) | U19: =IF(OR($F19="",$F19=0,$R19=""),"",$R19/$F19-1)
A20: 17 | G20: =IF(OR($E20="",$F20=""),"",$E20*$F20) | I20: =IF(OR($E20="",H20=""),"",$E20*H20) | K20: =IF(OR($E20="",J20=""),"",$E20*J20) | M20: =IF(OR($E20="",L20=""),"",$E20*L20) | O20: =IF(OR($E20="",N20=""),"",$E20*N20) | Q20: =IF(OR($E20="",P20=""),"",$E20*P20) | R20: =IF(MIN(IF(J20=0,9.9E+30,J20),IF(L20=0,9.9E+30,L20),IF(N20=0,9.9E+30,N20),IF(P20=0,9.9E+30,P20))>9E+30,"",MIN(IF(J20=0,9.9E+30,J20),IF(L20=0,9.9E+30,L20),IF(N20=0,9.9E+30,N20),IF(P20=0,9.9E+30,P20))) | S20: =IF($R20="","",IF(J20=$R20,$J$6,IF(L20=$R20,$L$6,IF(N20=$R20,$N$6,IF(P20=$R20,$P$6,""))))) | T20: =IF(OR($R20="",$E20=""),"",$E20*$R20) | U20: =IF(OR($F20="",$F20=0,$R20=""),"",$R20/$F20-1)
A21: Sub-total — Flooring & Stone | G21: =SUM(G17:G20) -> 0 | I21: =SUM(I17:I20) -> 0 | K21: =SUM(K17:K20) -> 0 | M21: =SUM(M17:M20) -> 0 | O21: =SUM(O17:O20) -> 0 | Q21: =SUM(Q17:Q20) -> 0 | T21: =SUM(T17:T20) -> 0

Sheet 5. False Ceiling
A1: RIPPOTAI ARCHITECTURE | 5. False Ceiling & Drywall Partitions — COMPARATIVE STATEMENT OF QUOTATIONS | Y1: =J6 -> Vendor 1 — name
A2: Project: | B2: =Comparison!B2 -> 0 | E2: Client: | F2: =Comparison!F2 -> 0 | L2: =Comparison!J2 -> 0 | Y2: =L6 -> Vendor 2 — name
E3: Prepared by: | K3: Date: | Y3: =N6 -> Vendor 3 — name
A5: COMMERCIAL SUMMARY — 5. False Ceiling & Drywall Partitions (auto-calculated)
A6: Metric | G6: In-house Budget | H6: BOQ Rate | J6: Vendor 1 — name | L6: Vendor 2 — name | N6: Vendor 3 — name | P6: Vendor 4 — name
A7: Sub-total | G7: =G21 -> 0 | I7: =I21 -> 0 | K7: =K21 -> 0 | M7: =M21 -> 0 | O7: =O21 -> 0 | Q7: =Q21 -> 0
A8: Total | G8: =G7 -> 0 | I8: =I7 -> 0 | K8: =K7 -> 0 | M8: =M7 -> 0 | O8: =O7 -> 0 | Q8: =Q7 -> 0
A9: Variance vs Budget (₹) | G9: — | I9: =IF(I8=0,"",I8-$G$8) | K9: =IF(K8=0,"",K8-$G$8) | M9: =IF(M8=0,"",M8-$G$8) | O9: =IF(O8=0,"",O8-$G$8) | Q9: =IF(Q8=0,"",Q8-$G$8)
A10: Variance vs Budget (%) | G10: — | I10: =IF(OR(I8=0,$G$8=0),"",I8/$G$8-1) | K10: =IF(OR(K8=0,$G$8=0),"",K8/$G$8-1) | M10: =IF(OR(M8=0,$G$8=0),"",M8/$G$8-1) | O10: =IF(OR(O8=0,$G$8=0),"",O8/$G$8-1) | Q10: =IF(OR(Q8=0,$G$8=0),"",Q8/$G$8-1)
A11: Rank (L1 = lowest) | G11: — | I11: — | K11: =IF(K8=0,"",1+IF(AND(M8>0,M8<K8),1,0)+IF(AND(O8>0,O8<K8),1,0)+IF(AND(Q8>0,Q8<K8),1,0)) | M11: =IF(M8=0,"",1+IF(AND(K8>0,K8<M8),1,0)+IF(AND(O8>0,O8<M8),1,0)+IF(AND(Q8>0,Q8<M8),1,0)) | O11: =IF(O8=0,"",1+IF(AND(K8>0,K8<O8),1,0)+IF(AND(M8>0,M8<O8),1,0)+IF(AND(Q8>0,Q8<O8),1,0)) | Q11: =IF(Q8=0,"",1+IF(AND(K8>0,K8<Q8),1,0)+IF(AND(M8>0,M8<Q8),1,0)+IF(AND(O8>0,O8<Q8),1,0))
A12: Line items not quoted | G12: — | I12: =IF(I8=0,"",COUNT($E$17:$E$20)-COUNT(H17:H20)) | K12: =IF(K8=0,"",COUNT($E$17:$E$20)-COUNT(J17:J20)) | M12: =IF(M8=0,"",COUNT($E$17:$E$20)-COUNT(L17:L20)) | O12: =IF(O8=0,"",COUNT($E$17:$E$20)-COUNT(N17:N20)) | Q12: =IF(Q8=0,"",COUNT($E$17:$E$20)-COUNT(P17:P20))
A13: QUALIFIED / FINALISED VENDOR (your selection — not automatic) | F13: Finalised Sub-total | H13: =IF($C13="","",IF($C13=J6,K7,IF($C13=L6,M7,IF($C13=N6,O7,IF($C13=P6,Q7,"")))))
A14: SCOPE, QUANTITY & IN-HOUSE BUDGET — 5. False Ceiling & Drywall Partitions | J14: =J6 -> Vendor 1 — name | L14: =L6 -> Vendor 2 — name | N14: =N6 -> Vendor 3 — name | P14: =P6 -> Vendor 4 — name | R14: L1 ANALYSIS (auto) | V14: REMARKS
A15: S.No | B15: Item Description | C15: Specification / Make | D15: Unit | E15: Qty | F15: Budget Rate | G15: Budget Amount | H15: BOQ Rate | I15: BOQ Amount | J15: Rate | K15: Amount | L15: Rate | M15: Amount | N15: Rate | O15: Amount | P15: Rate | Q15: Amount | R15: L1 Rate | S15: L1 Vendor | T15: L1 Amount | U15: L1 vs Budget | V15: Remarks / Qualification
A16: 5. False Ceiling & Drywall Partitions
A17: 18 | G17: =IF(OR($E17="",$F17=""),"",$E17*$F17) | I17: =IF(OR($E17="",H17=""),"",$E17*H17) | K17: =IF(OR($E17="",J17=""),"",$E17*J17) | M17: =IF(OR($E17="",L17=""),"",$E17*L17) | O17: =IF(OR($E17="",N17=""),"",$E17*N17) | Q17: =IF(OR($E17="",P17=""),"",$E17*P17) | R17: =IF(MIN(IF(J17=0,9.9E+30,J17),IF(L17=0,9.9E+30,L17),IF(N17=0,9.9E+30,N17),IF(P17=0,9.9E+30,P17))>9E+30,"",MIN(IF(J17=0,9.9E+30,J17),IF(L17=0,9.9E+30,L17),IF(N17=0,9.9E+30,N17),IF(P17=0,9.9E+30,P17))) | S17: =IF($R17="","",IF(J17=$R17,$J$6,IF(L17=$R17,$L$6,IF(N17=$R17,$N$6,IF(P17=$R17,$P$6,""))))) | T17: =IF(OR($R17="",$E17=""),"",$E17*$R17) | U17: =IF(OR($F17="",$F17=0,$R17=""),"",$R17/$F17-1)
A18: 19 | G18: =IF(OR($E18="",$F18=""),"",$E18*$F18) | I18: =IF(OR($E18="",H18=""),"",$E18*H18) | K18: =IF(OR($E18="",J18=""),"",$E18*J18) | M18: =IF(OR($E18="",L18=""),"",$E18*L18) | O18: =IF(OR($E18="",N18=""),"",$E18*N18) | Q18: =IF(OR($E18="",P18=""),"",$E18*P18) | R18: =IF(MIN(IF(J18=0,9.9E+30,J18),IF(L18=0,9.9E+30,L18),IF(N18=0,9.9E+30,N18),IF(P18=0,9.9E+30,P18))>9E+30,"",MIN(IF(J18=0,9.9E+30,J18),IF(L18=0,9.9E+30,L18),IF(N18=0,9.9E+30,N18),IF(P18=0,9.9E+30,P18))) | S18: =IF($R18="","",IF(J18=$R18,$J$6,IF(L18=$R18,$L$6,IF(N18=$R18,$N$6,IF(P18=$R18,$P$6,""))))) | T18: =IF(OR($R18="",$E18=""),"",$E18*$R18) | U18: =IF(OR($F18="",$F18=0,$R18=""),"",$R18/$F18-1)
A19: 20 | G19: =IF(OR($E19="",$F19=""),"",$E19*$F19) | I19: =IF(OR($E19="",H19=""),"",$E19*H19) | K19: =IF(OR($E19="",J19=""),"",$E19*J19) | M19: =IF(OR($E19="",L19=""),"",$E19*L19) | O19: =IF(OR($E19="",N19=""),"",$E19*N19) | Q19: =IF(OR($E19="",P19=""),"",$E19*P19) | R19: =IF(MIN(IF(J19=0,9.9E+30,J19),IF(L19=0,9.9E+30,L19),IF(N19=0,9.9E+30,N19),IF(P19=0,9.9E+30,P19))>9E+30,"",MIN(IF(J19=0,9.9E+30,J19),IF(L19=0,9.9E+30,L19),IF(N19=0,9.9E+30,N19),IF(P19=0,9.9E+30,P19))) | S19: =IF($R19="","",IF(J19=$R19,$J$6,IF(L19=$R19,$L$6,IF(N19=$R19,$N$6,IF(P19=$R19,$P$6,""))))) | T19: =IF(OR($R19="",$E19=""),"",$E19*$R19) | U19: =IF(OR($F19="",$F19=0,$R19=""),"",$R19/$F19-1)
A20: 21 | G20: =IF(OR($E20="",$F20=""),"",$E20*$F20) | I20: =IF(OR($E20="",H20=""),"",$E20*H20) | K20: =IF(OR($E20="",J20=""),"",$E20*J20) | M20: =IF(OR($E20="",L20=""),"",$E20*L20) | O20: =IF(OR($E20="",N20=""),"",$E20*N20) | Q20: =IF(OR($E20="",P20=""),"",$E20*P20) | R20: =IF(MIN(IF(J20=0,9.9E+30,J20),IF(L20=0,9.9E+30,L20),IF(N20=0,9.9E+30,N20),IF(P20=0,9.9E+30,P20))>9E+30,"",MIN(IF(J20=0,9.9E+30,J20),IF(L20=0,9.9E+30,L20),IF(N20=0,9.9E+30,N20),IF(P20=0,9.9E+30,P20))) | S20: =IF($R20="","",IF(J20=$R20,$J$6,IF(L20=$R20,$L$6,IF(N20=$R20,$N$6,IF(P20=$R20,$P$6,""))))) | T20: =IF(OR($R20="",$E20=""),"",$E20*$R20) | U20: =IF(OR($F20="",$F20=0,$R20=""),"",$R20/$F20-1)
A21: Sub-total — False Ceiling & Drywall Partitions | G21: =SUM(G17:G20) -> 0 | I21: =SUM(I17:I20) -> 0 | K21: =SUM(K17:K20) -> 0 | M21: =SUM(M17:M20) -> 0 | O21: =SUM(O17:O20) -> 0 | Q21: =SUM(Q17:Q20) -> 0 | T21: =SUM(T17:T20) -> 0

Sheet 6. Carpentry
A1: RIPPOTAI ARCHITECTURE | 6. Carpentry & Joinery — COMPARATIVE STATEMENT OF QUOTATIONS | Y1: =J6 -> Vendor 1 — name
A2: Project: | B2: =Comparison!B2 -> 0 | E2: Client: | F2: =Comparison!F2 -> 0 | L2: =Comparison!J2 -> 0 | Y2: =L6 -> Vendor 2 — name
E3: Prepared by: | K3: Date: | Y3: =N6 -> Vendor 3 — name
A5: COMMERCIAL SUMMARY — 6. Carpentry & Joinery (auto-calculated)
A6: Metric | G6: In-house Budget | H6: BOQ Rate | J6: Vendor 1 — name | L6: Vendor 2 — name | N6: Vendor 3 — name | P6: Vendor 4 — name
A7: Sub-total | G7: =G21 -> 0 | I7: =I21 -> 0 | K7: =K21 -> 0 | M7: =M21 -> 0 | O7: =O21 -> 0 | Q7: =Q21 -> 0
A8: Total | G8: =G7 -> 0 | I8: =I7 -> 0 | K8: =K7 -> 0 | M8: =M7 -> 0 | O8: =O7 -> 0 | Q8: =Q7 -> 0
A9: Variance vs Budget (₹) | G9: — | I9: =IF(I8=0,"",I8-$G$8) | K9: =IF(K8=0,"",K8-$G$8) | M9: =IF(M8=0,"",M8-$G$8) | O9: =IF(O8=0,"",O8-$G$8) | Q9: =IF(Q8=0,"",Q8-$G$8)
A10: Variance vs Budget (%) | G10: — | I10: =IF(OR(I8=0,$G$8=0),"",I8/$G$8-1) | K10: =IF(OR(K8=0,$G$8=0),"",K8/$G$8-1) | M10: =IF(OR(M8=0,$G$8=0),"",M8/$G$8-1) | O10: =IF(OR(O8=0,$G$8=0),"",O8/$G$8-1) | Q10: =IF(OR(Q8=0,$G$8=0),"",Q8/$G$8-1)
A11: Rank (L1 = lowest) | G11: — | I11: — | K11: =IF(K8=0,"",1+IF(AND(M8>0,M8<K8),1,0)+IF(AND(O8>0,O8<K8),1,0)+IF(AND(Q8>0,Q8<K8),1,0)) | M11: =IF(M8=0,"",1+IF(AND(K8>0,K8<M8),1,0)+IF(AND(O8>0,O8<M8),1,0)+IF(AND(Q8>0,Q8<M8),1,0)) | O11: =IF(O8=0,"",1+IF(AND(K8>0,K8<O8),1,0)+IF(AND(M8>0,M8<O8),1,0)+IF(AND(Q8>0,Q8<O8),1,0)) | Q11: =IF(Q8=0,"",1+IF(AND(K8>0,K8<Q8),1,0)+IF(AND(M8>0,M8<Q8),1,0)+IF(AND(O8>0,O8<Q8),1,0))
A12: Line items not quoted | G12: — | I12: =IF(I8=0,"",COUNT($E$17:$E$20)-COUNT(H17:H20)) | K12: =IF(K8=0,"",COUNT($E$17:$E$20)-COUNT(J17:J20)) | M12: =IF(M8=0,"",COUNT($E$17:$E$20)-COUNT(L17:L20)) | O12: =IF(O8=0,"",COUNT($E$17:$E$20)-COUNT(N17:N20)) | Q12: =IF(Q8=0,"",COUNT($E$17:$E$20)-COUNT(P17:P20))
A13: QUALIFIED / FINALISED VENDOR (your selection — not automatic) | F13: Finalised Sub-total | H13: =IF($C13="","",IF($C13=J6,K7,IF($C13=L6,M7,IF($C13=N6,O7,IF($C13=P6,Q7,"")))))
A14: SCOPE, QUANTITY & IN-HOUSE BUDGET — 6. Carpentry & Joinery | J14: =J6 -> Vendor 1 — name | L14: =L6 -> Vendor 2 — name | N14: =N6 -> Vendor 3 — name | P14: =P6 -> Vendor 4 — name | R14: L1 ANALYSIS (auto) | V14: REMARKS
A15: S.No | B15: Item Description | C15: Specification / Make | D15: Unit | E15: Qty | F15: Budget Rate | G15: Budget Amount | H15: BOQ Rate | I15: BOQ Amount | J15: Rate | K15: Amount | L15: Rate | M15: Amount | N15: Rate | O15: Amount | P15: Rate | Q15: Amount | R15: L1 Rate | S15: L1 Vendor | T15: L1 Amount | U15: L1 vs Budget | V15: Remarks / Qualification
A16: 6. Carpentry & Joinery
A17: 22 | G17: =IF(OR($E17="",$F17=""),"",$E17*$F17) | I17: =IF(OR($E17="",H17=""),"",$E17*H17) | K17: =IF(OR($E17="",J17=""),"",$E17*J17) | M17: =IF(OR($E17="",L17=""),"",$E17*L17) | O17: =IF(OR($E17="",N17=""),"",$E17*N17) | Q17: =IF(OR($E17="",P17=""),"",$E17*P17) | R17: =IF(MIN(IF(J17=0,9.9E+30,J17),IF(L17=0,9.9E+30,L17),IF(N17=0,9.9E+30,N17),IF(P17=0,9.9E+30,P17))>9E+30,"",MIN(IF(J17=0,9.9E+30,J17),IF(L17=0,9.9E+30,L17),IF(N17=0,9.9E+30,N17),IF(P17=0,9.9E+30,P17))) | S17: =IF($R17="","",IF(J17=$R17,$J$6,IF(L17=$R17,$L$6,IF(N17=$R17,$N$6,IF(P17=$R17,$P$6,""))))) | T17: =IF(OR($R17="",$E17=""),"",$E17*$R17) | U17: =IF(OR($F17="",$F17=0,$R17=""),"",$R17/$F17-1)
A18: 23 | G18: =IF(OR($E18="",$F18=""),"",$E18*$F18) | I18: =IF(OR($E18="",H18=""),"",$E18*H18) | K18: =IF(OR($E18="",J18=""),"",$E18*J18) | M18: =IF(OR($E18="",L18=""),"",$E18*L18) | O18: =IF(OR($E18="",N18=""),"",$E18*N18) | Q18: =IF(OR($E18="",P18=""),"",$E18*P18) | R18: =IF(MIN(IF(J18=0,9.9E+30,J18),IF(L18=0,9.9E+30,L18),IF(N18=0,9.9E+30,N18),IF(P18=0,9.9E+30,P18))>9E+30,"",MIN(IF(J18=0,9.9E+30,J18),IF(L18=0,9.9E+30,L18),IF(N18=0,9.9E+30,N18),IF(P18=0,9.9E+30,P18))) | S18: =IF($R18="","",IF(J18=$R18,$J$6,IF(L18=$R18,$L$6,IF(N18=$R18,$N$6,IF(P18=$R18,$P$6,""))))) | T18: =IF(OR($R18="",$E18=""),"",$E18*$R18) | U18: =IF(OR($F18="",$F18=0,$R18=""),"",$R18/$F18-1)
A19: 24 | G19: =IF(OR($E19="",$F19=""),"",$E19*$F19) | I19: =IF(OR($E19="",H19=""),"",$E19*H19) | K19: =IF(OR($E19="",J19=""),"",$E19*J19) | M19: =IF(OR($E19="",L19=""),"",$E19*L19) | O19: =IF(OR($E19="",N19=""),"",$E19*N19) | Q19: =IF(OR($E19="",P19=""),"",$E19*P19) | R19: =IF(MIN(IF(J19=0,9.9E+30,J19),IF(L19=0,9.9E+30,L19),IF(N19=0,9.9E+30,N19),IF(P19=0,9.9E+30,P19))>9E+30,"",MIN(IF(J19=0,9.9E+30,J19),IF(L19=0,9.9E+30,L19),IF(N19=0,9.9E+30,N19),IF(P19=0,9.9E+30,P19))) | S19: =IF($R19="","",IF(J19=$R19,$J$6,IF(L19=$R19,$L$6,IF(N19=$R19,$N$6,IF(P19=$R19,$P$6,""))))) | T19: =IF(OR($R19="",$E19=""),"",$E19*$R19) | U19: =IF(OR($F19="",$F19=0,$R19=""),"",$R19/$F19-1)
A20: 25 | G20: =IF(OR($E20="",$F20=""),"",$E20*$F20) | I20: =IF(OR($E20="",H20=""),"",$E20*H20) | K20: =IF(OR($E20="",J20=""),"",$E20*J20) | M20: =IF(OR($E20="",L20=""),"",$E20*L20) | O20: =IF(OR($E20="",N20=""),"",$E20*N20) | Q20: =IF(OR($E20="",P20=""),"",$E20*P20) | R20: =IF(MIN(IF(J20=0,9.9E+30,J20),IF(L20=0,9.9E+30,L20),IF(N20=0,9.9E+30,N20),IF(P20=0,9.9E+30,P20))>9E+30,"",MIN(IF(J20=0,9.9E+30,J20),IF(L20=0,9.9E+30,L20),IF(N20=0,9.9E+30,N20),IF(P20=0,9.9E+30,P20))) | S20: =IF($R20="","",IF(J20=$R20,$J$6,IF(L20=$R20,$L$6,IF(N20=$R20,$N$6,IF(P20=$R20,$P$6,""))))) | T20: =IF(OR($R20="",$E20=""),"",$E20*$R20) | U20: =IF(OR($F20="",$F20=0,$R20=""),"",$R20/$F20-1)
A21: Sub-total — Carpentry & Joinery | G21: =SUM(G17:G20) -> 0 | I21: =SUM(I17:I20) -> 0 | K21: =SUM(K17:K20) -> 0 | M21: =SUM(M17:M20) -> 0 | O21: =SUM(O17:O20) -> 0 | Q21: =SUM(Q17:Q20) -> 0 | T21: =SUM(T17:T20) -> 0

Sheet 7. Glass & Alu
A1: RIPPOTAI ARCHITECTURE | 7. Glass, Aluminium & Hardware — COMPARATIVE STATEMENT OF QUOTATIONS | Y1: =J6 -> Vendor 1 — name
A2: Project: | B2: =Comparison!B2 -> 0 | E2: Client: | F2: =Comparison!F2 -> 0 | L2: =Comparison!J2 -> 0 | Y2: =L6 -> Vendor 2 — name
E3: Prepared by: | K3: Date: | Y3: =N6 -> Vendor 3 — name
A5: COMMERCIAL SUMMARY — 7. Glass, Aluminium & Hardware (auto-calculated)
A6: Metric | G6: In-house Budget | H6: BOQ Rate | J6: Vendor 1 — name | L6: Vendor 2 — name | N6: Vendor 3 — name | P6: Vendor 4 — name
A7: Sub-total | G7: =G21 -> 0 | I7: =I21 -> 0 | K7: =K21 -> 0 | M7: =M21 -> 0 | O7: =O21 -> 0 | Q7: =Q21 -> 0
A8: Total | G8: =G7 -> 0 | I8: =I7 -> 0 | K8: =K7 -> 0 | M8: =M7 -> 0 | O8: =O7 -> 0 | Q8: =Q7 -> 0
A9: Variance vs Budget (₹) | G9: — | I9: =IF(I8=0,"",I8-$G$8) | K9: =IF(K8=0,"",K8-$G$8) | M9: =IF(M8=0,"",M8-$G$8) | O9: =IF(O8=0,"",O8-$G$8) | Q9: =IF(Q8=0,"",Q8-$G$8)
A10: Variance vs Budget (%) | G10: — | I10: =IF(OR(I8=0,$G$8=0),"",I8/$G$8-1) | K10: =IF(OR(K8=0,$G$8=0),"",K8/$G$8-1) | M10: =IF(OR(M8=0,$G$8=0),"",M8/$G$8-1) | O10: =IF(OR(O8=0,$G$8=0),"",O8/$G$8-1) | Q10: =IF(OR(Q8=0,$G$8=0),"",Q8/$G$8-1)
A11: Rank (L1 = lowest) | G11: — | I11: — | K11: =IF(K8=0,"",1+IF(AND(M8>0,M8<K8),1,0)+IF(AND(O8>0,O8<K8),1,0)+IF(AND(Q8>0,Q8<K8),1,0)) | M11: =IF(M8=0,"",1+IF(AND(K8>0,K8<M8),1,0)+IF(AND(O8>0,O8<M8),1,0)+IF(AND(Q8>0,Q8<M8),1,0)) | O11: =IF(O8=0,"",1+IF(AND(K8>0,K8<O8),1,0)+IF(AND(M8>0,M8<O8),1,0)+IF(AND(Q8>0,Q8<O8),1,0)) | Q11: =IF(Q8=0,"",1+IF(AND(K8>0,K8<Q8),1,0)+IF(AND(M8>0,M8<Q8),1,0)+IF(AND(O8>0,O8<Q8),1,0))
A12: Line items not quoted | G12: — | I12: =IF(I8=0,"",COUNT($E$17:$E$20)-COUNT(H17:H20)) | K12: =IF(K8=0,"",COUNT($E$17:$E$20)-COUNT(J17:J20)) | M12: =IF(M8=0,"",COUNT($E$17:$E$20)-COUNT(L17:L20)) | O12: =IF(O8=0,"",COUNT($E$17:$E$20)-COUNT(N17:N20)) | Q12: =IF(Q8=0,"",COUNT($E$17:$E$20)-COUNT(P17:P20))
A13: QUALIFIED / FINALISED VENDOR (your selection — not automatic) | F13: Finalised Sub-total | H13: =IF($C13="","",IF($C13=J6,K7,IF($C13=L6,M7,IF($C13=N6,O7,IF($C13=P6,Q7,"")))))
A14: SCOPE, QUANTITY & IN-HOUSE BUDGET — 7. Glass, Aluminium & Hardware | J14: =J6 -> Vendor 1 — name | L14: =L6 -> Vendor 2 — name | N14: =N6 -> Vendor 3 — name | P14: =P6 -> Vendor 4 — name | R14: L1 ANALYSIS (auto) | V14: REMARKS
A15: S.No | B15: Item Description | C15: Specification / Make | D15: Unit | E15: Qty | F15: Budget Rate | G15: Budget Amount | H15: BOQ Rate | I15: BOQ Amount | J15: Rate | K15: Amount | L15: Rate | M15: Amount | N15: Rate | O15: Amount | P15: Rate | Q15: Amount | R15: L1 Rate | S15: L1 Vendor | T15: L1 Amount | U15: L1 vs Budget | V15: Remarks / Qualification
A16: 7. Glass, Aluminium & Hardware
A17: 26 | G17: =IF(OR($E17="",$F17=""),"",$E17*$F17) | I17: =IF(OR($E17="",H17=""),"",$E17*H17) | K17: =IF(OR($E17="",J17=""),"",$E17*J17) | M17: =IF(OR($E17="",L17=""),"",$E17*L17) | O17: =IF(OR($E17="",N17=""),"",$E17*N17) | Q17: =IF(OR($E17="",P17=""),"",$E17*P17) | R17: =IF(MIN(IF(J17=0,9.9E+30,J17),IF(L17=0,9.9E+30,L17),IF(N17=0,9.9E+30,N17),IF(P17=0,9.9E+30,P17))>9E+30,"",MIN(IF(J17=0,9.9E+30,J17),IF(L17=0,9.9E+30,L17),IF(N17=0,9.9E+30,N17),IF(P17=0,9.9E+30,P17))) | S17: =IF($R17="","",IF(J17=$R17,$J$6,IF(L17=$R17,$L$6,IF(N17=$R17,$N$6,IF(P17=$R17,$P$6,""))))) | T17: =IF(OR($R17="",$E17=""),"",$E17*$R17) | U17: =IF(OR($F17="",$F17=0,$R17=""),"",$R17/$F17-1)
A18: 27 | G18: =IF(OR($E18="",$F18=""),"",$E18*$F18) | I18: =IF(OR($E18="",H18=""),"",$E18*H18) | K18: =IF(OR($E18="",J18=""),"",$E18*J18) | M18: =IF(OR($E18="",L18=""),"",$E18*L18) | O18: =IF(OR($E18="",N18=""),"",$E18*N18) | Q18: =IF(OR($E18="",P18=""),"",$E18*P18) | R18: =IF(MIN(IF(J18=0,9.9E+30,J18),IF(L18=0,9.9E+30,L18),IF(N18=0,9.9E+30,N18),IF(P18=0,9.9E+30,P18))>9E+30,"",MIN(IF(J18=0,9.9E+30,J18),IF(L18=0,9.9E+30,L18),IF(N18=0,9.9E+30,N18),IF(P18=0,9.9E+30,P18))) | S18: =IF($R18="","",IF(J18=$R18,$J$6,IF(L18=$R18,$L$6,IF(N18=$R18,$N$6,IF(P18=$R18,$P$6,""))))) | T18: =IF(OR($R18="",$E18=""),"",$E18*$R18) | U18: =IF(OR($F18="",$F18=0,$R18=""),"",$R18/$F18-1)
A19: 28 | G19: =IF(OR($E19="",$F19=""),"",$E19*$F19) | I19: =IF(OR($E19="",H19=""),"",$E19*H19) | K19: =IF(OR($E19="",J19=""),"",$E19*J19) | M19: =IF(OR($E19="",L19=""),"",$E19*L19) | O19: =IF(OR($E19="",N19=""),"",$E19*N19) | Q19: =IF(OR($E19="",P19=""),"",$E19*P19) | R19: =IF(MIN(IF(J19=0,9.9E+30,J19),IF(L19=0,9.9E+30,L19),IF(N19=0,9.9E+30,N19),IF(P19=0,9.9E+30,P19))>9E+30,"",MIN(IF(J19=0,9.9E+30,J19),IF(L19=0,9.9E+30,L19),IF(N19=0,9.9E+30,N19),IF(P19=0,9.9E+30,P19))) | S19: =IF($R19="","",IF(J19=$R19,$J$6,IF(L19=$R19,$L$6,IF(N19=$R19,$N$6,IF(P19=$R19,$P$6,""))))) | T19: =IF(OR($R19="",$E19=""),"",$E19*$R19) | U19: =IF(OR($F19="",$F19=0,$R19=""),"",$R19/$F19-1)
A20: 29 | G20: =IF(OR($E20="",$F20=""),"",$E20*$F20) | I20: =IF(OR($E20="",H20=""),"",$E20*H20) | K20: =IF(OR($E20="",J20=""),"",$E20*J20) | M20: =IF(OR($E20="",L20=""),"",$E20*L20) | O20: =IF(OR($E20="",N20=""),"",$E20*N20) | Q20: =IF(OR($E20="",P20=""),"",$E20*P20) | R20: =IF(MIN(IF(J20=0,9.9E+30,J20),IF(L20=0,9.9E+30,L20),IF(N20=0,9.9E+30,N20),IF(P20=0,9.9E+30,P20))>9E+30,"",MIN(IF(J20=0,9.9E+30,J20),IF(L20=0,9.9E+30,L20),IF(N20=0,9.9E+30,N20),IF(P20=0,9.9E+30,P20))) | S20: =IF($R20="","",IF(J20=$R20,$J$6,IF(L20=$R20,$L$6,IF(N20=$R20,$N$6,IF(P20=$R20,$P$6,""))))) | T20: =IF(OR($R20="",$E20=""),"",$E20*$R20) | U20: =IF(OR($F20="",$F20=0,$R20=""),"",$R20/$F20-1)
A21: Sub-total — Glass, Aluminium & Hardware | G21: =SUM(G17:G20) -> 0 | I21: =SUM(I17:I20) -> 0 | K21: =SUM(K17:K20) -> 0 | M21: =SUM(M17:M20) -> 0 | O21: =SUM(O17:O20) -> 0 | Q21: =SUM(Q17:Q20) -> 0 | T21: =SUM(T17:T20) -> 0

Sheet 8. Electrical
A1: RIPPOTAI ARCHITECTURE | 8. Electrical & Low-Voltage — COMPARATIVE STATEMENT OF QUOTATIONS | Y1: =J6 -> Vendor 1 — name
A2: Project: | B2: =Comparison!B2 -> 0 | E2: Client: | F2: =Comparison!F2 -> 0 | L2: =Comparison!J2 -> 0 | Y2: =L6 -> Vendor 2 — name
E3: Prepared by: | K3: Date: | Y3: =N6 -> Vendor 3 — name
A5: COMMERCIAL SUMMARY — 8. Electrical & Low-Voltage (auto-calculated)
A6: Metric | G6: In-house Budget | H6: BOQ Rate | J6: Vendor 1 — name | L6: Vendor 2 — name | N6: Vendor 3 — name | P6: Vendor 4 — name
A7: Sub-total | G7: =G21 -> 0 | I7: =I21 -> 0 | K7: =K21 -> 0 | M7: =M21 -> 0 | O7: =O21 -> 0 | Q7: =Q21 -> 0
A8: Total | G8: =G7 -> 0 | I8: =I7 -> 0 | K8: =K7 -> 0 | M8: =M7 -> 0 | O8: =O7 -> 0 | Q8: =Q7 -> 0
A9: Variance vs Budget (₹) | G9: — | I9: =IF(I8=0,"",I8-$G$8) | K9: =IF(K8=0,"",K8-$G$8) | M9: =IF(M8=0,"",M8-$G$8) | O9: =IF(O8=0,"",O8-$G$8) | Q9: =IF(Q8=0,"",Q8-$G$8)
A10: Variance vs Budget (%) | G10: — | I10: =IF(OR(I8=0,$G$8=0),"",I8/$G$8-1) | K10: =IF(OR(K8=0,$G$8=0),"",K8/$G$8-1) | M10: =IF(OR(M8=0,$G$8=0),"",M8/$G$8-1) | O10: =IF(OR(O8=0,$G$8=0),"",O8/$G$8-1) | Q10: =IF(OR(Q8=0,$G$8=0),"",Q8/$G$8-1)
A11: Rank (L1 = lowest) | G11: — | I11: — | K11: =IF(K8=0,"",1+IF(AND(M8>0,M8<K8),1,0)+IF(AND(O8>0,O8<K8),1,0)+IF(AND(Q8>0,Q8<K8),1,0)) | M11: =IF(M8=0,"",1+IF(AND(K8>0,K8<M8),1,0)+IF(AND(O8>0,O8<M8),1,0)+IF(AND(Q8>0,Q8<M8),1,0)) | O11: =IF(O8=0,"",1+IF(AND(K8>0,K8<O8),1,0)+IF(AND(M8>0,M8<O8),1,0)+IF(AND(Q8>0,Q8<O8),1,0)) | Q11: =IF(Q8=0,"",1+IF(AND(K8>0,K8<Q8),1,0)+IF(AND(M8>0,M8<Q8),1,0)+IF(AND(O8>0,O8<Q8),1,0))
A12: Line items not quoted | G12: — | I12: =IF(I8=0,"",COUNT($E$17:$E$20)-COUNT(H17:H20)) | K12: =IF(K8=0,"",COUNT($E$17:$E$20)-COUNT(J17:J20)) | M12: =IF(M8=0,"",COUNT($E$17:$E$20)-COUNT(L17:L20)) | O12: =IF(O8=0,"",COUNT($E$17:$E$20)-COUNT(N17:N20)) | Q12: =IF(Q8=0,"",COUNT($E$17:$E$20)-COUNT(P17:P20))
A13: QUALIFIED / FINALISED VENDOR (your selection — not automatic) | F13: Finalised Sub-total | H13: =IF($C13="","",IF($C13=J6,K7,IF($C13=L6,M7,IF($C13=N6,O7,IF($C13=P6,Q7,"")))))
A14: SCOPE, QUANTITY & IN-HOUSE BUDGET — 8. Electrical & Low-Voltage | J14: =J6 -> Vendor 1 — name | L14: =L6 -> Vendor 2 — name | N14: =N6 -> Vendor 3 — name | P14: =P6 -> Vendor 4 — name | R14: L1 ANALYSIS (auto) | V14: REMARKS
A15: S.No | B15: Item Description | C15: Specification / Make | D15: Unit | E15: Qty | F15: Budget Rate | G15: Budget Amount | H15: BOQ Rate | I15: BOQ Amount | J15: Rate | K15: Amount | L15: Rate | M15: Amount | N15: Rate | O15: Amount | P15: Rate | Q15: Amount | R15: L1 Rate | S15: L1 Vendor | T15: L1 Amount | U15: L1 vs Budget | V15: Remarks / Qualification
A16: 8. Electrical & Low-Voltage
A17: 30 | G17: =IF(OR($E17="",$F17=""),"",$E17*$F17) | I17: =IF(OR($E17="",H17=""),"",$E17*H17) | K17: =IF(OR($E17="",J17=""),"",$E17*J17) | M17: =IF(OR($E17="",L17=""),"",$E17*L17) | O17: =IF(OR($E17="",N17=""),"",$E17*N17) | Q17: =IF(OR($E17="",P17=""),"",$E17*P17) | R17: =IF(MIN(IF(J17=0,9.9E+30,J17),IF(L17=0,9.9E+30,L17),IF(N17=0,9.9E+30,N17),IF(P17=0,9.9E+30,P17))>9E+30,"",MIN(IF(J17=0,9.9E+30,J17),IF(L17=0,9.9E+30,L17),IF(N17=0,9.9E+30,N17),IF(P17=0,9.9E+30,P17))) | S17: =IF($R17="","",IF(J17=$R17,$J$6,IF(L17=$R17,$L$6,IF(N17=$R17,$N$6,IF(P17=$R17,$P$6,""))))) | T17: =IF(OR($R17="",$E17=""),"",$E17*$R17) | U17: =IF(OR($F17="",$F17=0,$R17=""),"",$R17/$F17-1)
A18: 31 | G18: =IF(OR($E18="",$F18=""),"",$E18*$F18) | I18: =IF(OR($E18="",H18=""),"",$E18*H18) | K18: =IF(OR($E18="",J18=""),"",$E18*J18) | M18: =IF(OR($E18="",L18=""),"",$E18*L18) | O18: =IF(OR($E18="",N18=""),"",$E18*N18) | Q18: =IF(OR($E18="",P18=""),"",$E18*P18) | R18: =IF(MIN(IF(J18=0,9.9E+30,J18),IF(L18=0,9.9E+30,L18),IF(N18=0,9.9E+30,N18),IF(P18=0,9.9E+30,P18))>9E+30,"",MIN(IF(J18=0,9.9E+30,J18),IF(L18=0,9.9E+30,L18),IF(N18=0,9.9E+30,N18),IF(P18=0,9.9E+30,P18))) | S18: =IF($R18="","",IF(J18=$R18,$J$6,IF(L18=$R18,$L$6,IF(N18=$R18,$N$6,IF(P18=$R18,$P$6,""))))) | T18: =IF(OR($R18="",$E18=""),"",$E18*$R18) | U18: =IF(OR($F18="",$F18=0,$R18=""),"",$R18/$F18-1)
A19: 32 | G19: =IF(OR($E19="",$F19=""),"",$E19*$F19) | I19: =IF(OR($E19="",H19=""),"",$E19*H19) | K19: =IF(OR($E19="",J19=""),"",$E19*J19) | M19: =IF(OR($E19="",L19=""),"",$E19*L19) | O19: =IF(OR($E19="",N19=""),"",$E19*N19) | Q19: =IF(OR($E19="",P19=""),"",$E19*P19) | R19: =IF(MIN(IF(J19=0,9.9E+30,J19),IF(L19=0,9.9E+30,L19),IF(N19=0,9.9E+30,N19),IF(P19=0,9.9E+30,P19))>9E+30,"",MIN(IF(J19=0,9.9E+30,J19),IF(L19=0,9.9E+30,L19),IF(N19=0,9.9E+30,N19),IF(P19=0,9.9E+30,P19))) | S19: =IF($R19="","",IF(J19=$R19,$J$6,IF(L19=$R19,$L$6,IF(N19=$R19,$N$6,IF(P19=$R19,$P$6,""))))) | T19: =IF(OR($R19="",$E19=""),"",$E19*$R19) | U19: =IF(OR($F19="",$F19=0,$R19=""),"",$R19/$F19-1)
A20: 33 | G20: =IF(OR($E20="",$F20=""),"",$E20*$F20) | I20: =IF(OR($E20="",H20=""),"",$E20*H20) | K20: =IF(OR($E20="",J20=""),"",$E20*J20) | M20: =IF(OR($E20="",L20=""),"",$E20*L20) | O20: =IF(OR($E20="",N20=""),"",$E20*N20) | Q20: =IF(OR($E20="",P20=""),"",$E20*P20) | R20: =IF(MIN(IF(J20=0,9.9E+30,J20),IF(L20=0,9.9E+30,L20),IF(N20=0,9.9E+30,N20),IF(P20=0,9.9E+30,P20))>9E+30,"",MIN(IF(J20=0,9.9E+30,J20),IF(L20=0,9.9E+30,L20),IF(N20=0,9.9E+30,N20),IF(P20=0,9.9E+30,P20))) | S20: =IF($R20="","",IF(J20=$R20,$J$6,IF(L20=$R20,$L$6,IF(N20=$R20,$N$6,IF(P20=$R20,$P$6,""))))) | T20: =IF(OR($R20="",$E20=""),"",$E20*$R20) | U20: =IF(OR($F20="",$F20=0,$R20=""),"",$R20/$F20-1)
A21: Sub-total — Electrical & Low-Voltage | G21: =SUM(G17:G20) -> 0 | I21: =SUM(I17:I20) -> 0 | K21: =SUM(K17:K20) -> 0 | M21: =SUM(M17:M20) -> 0 | O21: =SUM(O17:O20) -> 0 | Q21: =SUM(Q17:Q20) -> 0 | T21: =SUM(T17:T20) -> 0

Sheet 9. Plumbing
A1: RIPPOTAI ARCHITECTURE | 9. Plumbing & Sanitary — COMPARATIVE STATEMENT OF QUOTATIONS | Y1: =J6 -> Vendor 1 — name
A2: Project: | B2: =Comparison!B2 -> 0 | E2: Client: | F2: =Comparison!F2 -> 0 | L2: =Comparison!J2 -> 0 | Y2: =L6 -> Vendor 2 — name
E3: Prepared by: | K3: Date: | Y3: =N6 -> Vendor 3 — name
A5: COMMERCIAL SUMMARY — 9. Plumbing & Sanitary (auto-calculated)
A6: Metric | G6: In-house Budget | H6: BOQ Rate | J6: Vendor 1 — name | L6: Vendor 2 — name | N6: Vendor 3 — name | P6: Vendor 4 — name
A7: Sub-total | G7: =G21 -> 0 | I7: =I21 -> 0 | K7: =K21 -> 0 | M7: =M21 -> 0 | O7: =O21 -> 0 | Q7: =Q21 -> 0
A8: Total | G8: =G7 -> 0 | I8: =I7 -> 0 | K8: =K7 -> 0 | M8: =M7 -> 0 | O8: =O7 -> 0 | Q8: =Q7 -> 0
A9: Variance vs Budget (₹) | G9: — | I9: =IF(I8=0,"",I8-$G$8) | K9: =IF(K8=0,"",K8-$G$8) | M9: =IF(M8=0,"",M8-$G$8) | O9: =IF(O8=0,"",O8-$G$8) | Q9: =IF(Q8=0,"",Q8-$G$8)
A10: Variance vs Budget (%) | G10: — | I10: =IF(OR(I8=0,$G$8=0),"",I8/$G$8-1) | K10: =IF(OR(K8=0,$G$8=0),"",K8/$G$8-1) | M10: =IF(OR(M8=0,$G$8=0),"",M8/$G$8-1) | O10: =IF(OR(O8=0,$G$8=0),"",O8/$G$8-1) | Q10: =IF(OR(Q8=0,$G$8=0),"",Q8/$G$8-1)
A11: Rank (L1 = lowest) | G11: — | I11: — | K11: =IF(K8=0,"",1+IF(AND(M8>0,M8<K8),1,0)+IF(AND(O8>0,O8<K8),1,0)+IF(AND(Q8>0,Q8<K8),1,0)) | M11: =IF(M8=0,"",1+IF(AND(K8>0,K8<M8),1,0)+IF(AND(O8>0,O8<M8),1,0)+IF(AND(Q8>0,Q8<M8),1,0)) | O11: =IF(O8=0,"",1+IF(AND(K8>0,K8<O8),1,0)+IF(AND(M8>0,M8<O8),1,0)+IF(AND(Q8>0,Q8<O8),1,0)) | Q11: =IF(Q8=0,"",1+IF(AND(K8>0,K8<Q8),1,0)+IF(AND(M8>0,M8<Q8),1,0)+IF(AND(O8>0,O8<Q8),1,0))
A12: Line items not quoted | G12: — | I12: =IF(I8=0,"",COUNT($E$17:$E$20)-COUNT(H17:H20)) | K12: =IF(K8=0,"",COUNT($E$17:$E$20)-COUNT(J17:J20)) | M12: =IF(M8=0,"",COUNT($E$17:$E$20)-COUNT(L17:L20)) | O12: =IF(O8=0,"",COUNT($E$17:$E$20)-COUNT(N17:N20)) | Q12: =IF(Q8=0,"",COUNT($E$17:$E$20)-COUNT(P17:P20))
A13: QUALIFIED / FINALISED VENDOR (your selection — not automatic) | F13: Finalised Sub-total | H13: =IF($C13="","",IF($C13=J6,K7,IF($C13=L6,M7,IF($C13=N6,O7,IF($C13=P6,Q7,"")))))
A14: SCOPE, QUANTITY & IN-HOUSE BUDGET — 9. Plumbing & Sanitary | J14: =J6 -> Vendor 1 — name | L14: =L6 -> Vendor 2 — name | N14: =N6 -> Vendor 3 — name | P14: =P6 -> Vendor 4 — name | R14: L1 ANALYSIS (auto) | V14: REMARKS
A15: S.No | B15: Item Description | C15: Specification / Make | D15: Unit | E15: Qty | F15: Budget Rate | G15: Budget Amount | H15: BOQ Rate | I15: BOQ Amount | J15: Rate | K15: Amount | L15: Rate | M15: Amount | N15: Rate | O15: Amount | P15: Rate | Q15: Amount | R15: L1 Rate | S15: L1 Vendor | T15: L1 Amount | U15: L1 vs Budget | V15: Remarks / Qualification
A16: 9. Plumbing & Sanitary
A17: 34 | G17: =IF(OR($E17="",$F17=""),"",$E17*$F17) | I17: =IF(OR($E17="",H17=""),"",$E17*H17) | K17: =IF(OR($E17="",J17=""),"",$E17*J17) | M17: =IF(OR($E17="",L17=""),"",$E17*L17) | O17: =IF(OR($E17="",N17=""),"",$E17*N17) | Q17: =IF(OR($E17="",P17=""),"",$E17*P17) | R17: =IF(MIN(IF(J17=0,9.9E+30,J17),IF(L17=0,9.9E+30,L17),IF(N17=0,9.9E+30,N17),IF(P17=0,9.9E+30,P17))>9E+30,"",MIN(IF(J17=0,9.9E+30,J17),IF(L17=0,9.9E+30,L17),IF(N17=0,9.9E+30,N17),IF(P17=0,9.9E+30,P17))) | S17: =IF($R17="","",IF(J17=$R17,$J$6,IF(L17=$R17,$L$6,IF(N17=$R17,$N$6,IF(P17=$R17,$P$6,""))))) | T17: =IF(OR($R17="",$E17=""),"",$E17*$R17) | U17: =IF(OR($F17="",$F17=0,$R17=""),"",$R17/$F17-1)
A18: 35 | G18: =IF(OR($E18="",$F18=""),"",$E18*$F18) | I18: =IF(OR($E18="",H18=""),"",$E18*H18) | K18: =IF(OR($E18="",J18=""),"",$E18*J18) | M18: =IF(OR($E18="",L18=""),"",$E18*L18) | O18: =IF(OR($E18="",N18=""),"",$E18*N18) | Q18: =IF(OR($E18="",P18=""),"",$E18*P18) | R18: =IF(MIN(IF(J18=0,9.9E+30,J18),IF(L18=0,9.9E+30,L18),IF(N18=0,9.9E+30,N18),IF(P18=0,9.9E+30,P18))>9E+30,"",MIN(IF(J18=0,9.9E+30,J18),IF(L18=0,9.9E+30,L18),IF(N18=0,9.9E+30,N18),IF(P18=0,9.9E+30,P18))) | S18: =IF($R18="","",IF(J18=$R18,$J$6,IF(L18=$R18,$L$6,IF(N18=$R18,$N$6,IF(P18=$R18,$P$6,""))))) | T18: =IF(OR($R18="",$E18=""),"",$E18*$R18) | U18: =IF(OR($F18="",$F18=0,$R18=""),"",$R18/$F18-1)
A19: 36 | G19: =IF(OR($E19="",$F19=""),"",$E19*$F19) | I19: =IF(OR($E19="",H19=""),"",$E19*H19) | K19: =IF(OR($E19="",J19=""),"",$E19*J19) | M19: =IF(OR($E19="",L19=""),"",$E19*L19) | O19: =IF(OR($E19="",N19=""),"",$E19*N19) | Q19: =IF(OR($E19="",P19=""),"",$E19*P19) | R19: =IF(MIN(IF(J19=0,9.9E+30,J19),IF(L19=0,9.9E+30,L19),IF(N19=0,9.9E+30,N19),IF(P19=0,9.9E+30,P19))>9E+30,"",MIN(IF(J19=0,9.9E+30,J19),IF(L19=0,9.9E+30,L19),IF(N19=0,9.9E+30,N19),IF(P19=0,9.9E+30,P19))) | S19: =IF($R19="","",IF(J19=$R19,$J$6,IF(L19=$R19,$L$6,IF(N19=$R19,$N$6,IF(P19=$R19,$P$6,""))))) | T19: =IF(OR($R19="",$E19=""),"",$E19*$R19) | U19: =IF(OR($F19="",$F19=0,$R19=""),"",$R19/$F19-1)
A20: 37 | G20: =IF(OR($E20="",$F20=""),"",$E20*$F20) | I20: =IF(OR($E20="",H20=""),"",$E20*H20) | K20: =IF(OR($E20="",J20=""),"",$E20*J20) | M20: =IF(OR($E20="",L20=""),"",$E20*L20) | O20: =IF(OR($E20="",N20=""),"",$E20*N20) | Q20: =IF(OR($E20="",P20=""),"",$E20*P20) | R20: =IF(MIN(IF(J20=0,9.9E+30,J20),IF(L20=0,9.9E+30,L20),IF(N20=0,9.9E+30,N20),IF(P20=0,9.9E+30,P20))>9E+30,"",MIN(IF(J20=0,9.9E+30,J20),IF(L20=0,9.9E+30,L20),IF(N20=0,9.9E+30,N20),IF(P20=0,9.9E+30,P20))) | S20: =IF($R20="","",IF(J20=$R20,$J$6,IF(L20=$R20,$L$6,IF(N20=$R20,$N$6,IF(P20=$R20,$P$6,""))))) | T20: =IF(OR($R20="",$E20=""),"",$E20*$R20) | U20: =IF(OR($F20="",$F20=0,$R20=""),"",$R20/$F20-1)
A21: Sub-total — Plumbing & Sanitary | G21: =SUM(G17:G20) -> 0 | I21: =SUM(I17:I20) -> 0 | K21: =SUM(K17:K20) -> 0 | M21: =SUM(M17:M20) -> 0 | O21: =SUM(O17:O20) -> 0 | Q21: =SUM(Q17:Q20) -> 0 | T21: =SUM(T17:T20) -> 0

Sheet 10. HVAC
A1: RIPPOTAI ARCHITECTURE | 10. HVAC — COMPARATIVE STATEMENT OF QUOTATIONS | Y1: =J6 -> Vendor 1 — name
A2: Project: | B2: =Comparison!B2 -> 0 | E2: Client: | F2: =Comparison!F2 -> 0 | L2: =Comparison!J2 -> 0 | Y2: =L6 -> Vendor 2 — name
E3: Prepared by: | K3: Date: | Y3: =N6 -> Vendor 3 — name
A5: COMMERCIAL SUMMARY — 10. HVAC (auto-calculated)
A6: Metric | G6: In-house Budget | H6: BOQ Rate | J6: Vendor 1 — name | L6: Vendor 2 — name | N6: Vendor 3 — name | P6: Vendor 4 — name
A7: Sub-total | G7: =G21 -> 0 | I7: =I21 -> 0 | K7: =K21 -> 0 | M7: =M21 -> 0 | O7: =O21 -> 0 | Q7: =Q21 -> 0
A8: Total | G8: =G7 -> 0 | I8: =I7 -> 0 | K8: =K7 -> 0 | M8: =M7 -> 0 | O8: =O7 -> 0 | Q8: =Q7 -> 0
A9: Variance vs Budget (₹) | G9: — | I9: =IF(I8=0,"",I8-$G$8) | K9: =IF(K8=0,"",K8-$G$8) | M9: =IF(M8=0,"",M8-$G$8) | O9: =IF(O8=0,"",O8-$G$8) | Q9: =IF(Q8=0,"",Q8-$G$8)
A10: Variance vs Budget (%) | G10: — | I10: =IF(OR(I8=0,$G$8=0),"",I8/$G$8-1) | K10: =IF(OR(K8=0,$G$8=0),"",K8/$G$8-1) | M10: =IF(OR(M8=0,$G$8=0),"",M8/$G$8-1) | O10: =IF(OR(O8=0,$G$8=0),"",O8/$G$8-1) | Q10: =IF(OR(Q8=0,$G$8=0),"",Q8/$G$8-1)
A11: Rank (L1 = lowest) | G11: — | I11: — | K11: =IF(K8=0,"",1+IF(AND(M8>0,M8<K8),1,0)+IF(AND(O8>0,O8<K8),1,0)+IF(AND(Q8>0,Q8<K8),1,0)) | M11: =IF(M8=0,"",1+IF(AND(K8>0,K8<M8),1,0)+IF(AND(O8>0,O8<M8),1,0)+IF(AND(Q8>0,Q8<M8),1,0)) | O11: =IF(O8=0,"",1+IF(AND(K8>0,K8<O8),1,0)+IF(AND(M8>0,M8<O8),1,0)+IF(AND(Q8>0,Q8<O8),1,0)) | Q11: =IF(Q8=0,"",1+IF(AND(K8>0,K8<Q8),1,0)+IF(AND(M8>0,M8<Q8),1,0)+IF(AND(O8>0,O8<Q8),1,0))
A12: Line items not quoted | G12: — | I12: =IF(I8=0,"",COUNT($E$17:$E$20)-COUNT(H17:H20)) | K12: =IF(K8=0,"",COUNT($E$17:$E$20)-COUNT(J17:J20)) | M12: =IF(M8=0,"",COUNT($E$17:$E$20)-COUNT(L17:L20)) | O12: =IF(O8=0,"",COUNT($E$17:$E$20)-COUNT(N17:N20)) | Q12: =IF(Q8=0,"",COUNT($E$17:$E$20)-COUNT(P17:P20))
A13: QUALIFIED / FINALISED VENDOR (your selection — not automatic) | F13: Finalised Sub-total | H13: =IF($C13="","",IF($C13=J6,K7,IF($C13=L6,M7,IF($C13=N6,O7,IF($C13=P6,Q7,"")))))
A14: SCOPE, QUANTITY & IN-HOUSE BUDGET — 10. HVAC | J14: =J6 -> Vendor 1 — name | L14: =L6 -> Vendor 2 — name | N14: =N6 -> Vendor 3 — name | P14: =P6 -> Vendor 4 — name | R14: L1 ANALYSIS (auto) | V14: REMARKS
